Workbook

Sheet Forge Components
A1: Force mass craft? | C1: FALSE | D1: Checklist | L1: FALSE | M1: FALSE | O1: FALSE | P1: FALSE | Q1: FALSE | R1: FALSE | S1: FALSE | T1: FALSE | U1: FALSE | V1: FALSE | W1: FALSE | X1: FALSE | Y1: FALSE | Z1: FALSE | AA1: FALSE | AB1: FALSE | AC1: FALSE | AD1: FALSE | AE1: FALSE | AF1: FALSE | AG1: FALSE | AH1: FALSE | AI1: FALSE | AJ1: FALSE | AK1: FALSE | AL1: FALSE | AM1: FALSE | AN1: FALSE | AO1: FALSE | AP1: FALSE | AQ1: FALSE | AR1: FALSE | AS1: FALSE | AT1: FALSE | AU1: FALSE | AV1: FALSE | AW1: FALSE | AX1: FALSE | AY1: FALSE | AZ1: FALSE | BA1: FALSE | BB1: FALSE | BC1: FALSE
A2: Autowant base component? | C2: TRUE | D2: Total Need | K2: =SUM(J11:J75) -> 6869 | L2: =SUM(BE5:BE75) -> 27900 | M2: =MAX(BF5:BF75) -> 3000 | O2: =SUM(BH5:BH75) -> 32 | P2: =SUM(BI5:BI75) -> 45 | Q2: =SUM(BJ5:BJ75) -> 4 | R2: =SUM(BK5:BK75) -> 0 | S2: =SUM(BL5:BL75) -> 35 | T2: =SUM(BM5:BM75) -> 22 | U2: =SUM(BN5:BN75) -> 26 | V2: =SUM(BO5:BO75) -> 0 | ... AA2: =SUM(BT5:BT75) -> 60 | AB2: =SUM(BV5:BV75) -> 0 | AC2: =SUM(BU5:BU75) -> 6 | AD2: =SUM(BW5:BW75) -> 4 | AE2: =SUM(BX5:BX75) -> 0 | AF2: =SUM(BZ5:BZ75) -> 4 | AG2: =SUM(CB5:CB75) -> 10 | AH2: =SUM(CA5:CA75) -> 3 | AI2: =SUM(BY5:BY75) -> 0 | AJ2: =SUM(CC5:CC75) -> 0 | AK2: =SUM(CF5:CF75) -> 0 | AL2: =SUM(CE5:CE75) -> 7 | AM2: =SUM(CD5:CD75) -> 0 | AN2: =SUM(CG5:CG75) -> 0 | AO2: =SUM(CJ5:CJ75) -> 0 | AP2: =SUM(CI5:CI75) -> 0 | AQ2: =SUM(CH5:CH75) -> 0 | AR2: =SUM(CK5:CK75) -> 24 | AS2: =SUM(CL5:CL75) -> 1 | AT2: =SUM(CM5:CM75) -> 0 | AU2: =SUM(CN5:CN75) -> 0 | AV2: =SUM(CO5:CO75) -> 45 | AW2: =SUM(CP5:CP75) -> 48 | AX2: =SUM(CQ5:CQ75) -> 24 | AY2: =SUM(CR5:CR75) -> 40 | ... BC2: =SUM(CV5:CV75) -> 139 | BH2: =VLOOKUP(BH4,'Price Data'!$A:$B,2,FALSE) -> 4 | BI2: =VLOOKUP(BI4,'Price Data'!$A:$B,2,FALSE) -> 3 | BJ2: =VLOOKUP(BJ4,'Price Data'!$A:$B,2,FALSE) -> 10 | BK2: =VLOOKUP(BK4,'Price Data'!$A:$B,2,FALSE) -> 5 | BL2: =VLOOKUP(BL4,'Price Data'!$A:$B,2,FALSE) -> 50 | BM2: =VLOOKUP(BM4,'Price Data'!$A:$B,2,FALSE) -> 60 | BN2: =VLOOKUP(BN4,'Price Data'!$A:$B,2,FALSE) -> 60 | BO2: =VLOOKUP(BO4,'Price Data'!$A:$B,2,FALSE) -> 70 | ... CV2: =VLOOKUP(CV4,'Price Data'!$A:$B,2,FALSE) -> 4 | CX2: Total price to craft one
A3: =HYPERLINK("https://docs.google.com/spreadsheets/d/1Uy3IweykzeGsWOpNRR6Yx1TO4Y8c5qMbYHTlwK4BR8I/", "Forge Boon List") -> Forge Boon List | O3: =IFERROR(__xludf.DUMMYFUNCTION("IMAGE(CONCATENATE(""http://mayumi.fi/boundless/"",REGEXREPLACE(LOWER(O4),""\s"", ""%20""),"".png""),1)"),"#REF!") -> #REF! | P3: =IFERROR(__xludf.DUMMYFUNCTION("IMAGE(CONCATENATE(""http://mayumi.fi/boundless/"",REGEXREPLACE(LOWER(P4),""\s"", ""%20""),"".png""),1)"),"#REF!") -> #REF! | Q3: =IFERROR(__xludf.DUMMYFUNCTION("IMAGE(CONCATENATE(""http://mayumi.fi/boundless/"",REGEXREPLACE(LOWER(Q4),""\s"", ""%20""),"".png""),1)"),"#REF!") -> #REF! | R3: =IFERROR(__xludf.DUMMYFUNCTION("IMAGE(CONCATENATE(""http://mayumi.fi/boundless/"",REGEXREPLACE(LOWER(R4),""\s"", ""%20""),"".png""),1)"),"#REF!") -> #REF! | S3: =IFERROR(__xludf.DUMMYFUNCTION("IMAGE(CONCATENATE(""http://mayumi.fi/boundless/"",REGEXREPLACE(LOWER(S4),""\s"", ""%20""),"".png""),1)"),"#REF!") -> #REF! | T3: =IFERROR(__xludf.DUMMYFUNCTION("IMAGE(CONCATENATE(""http://mayumi.fi/boundless/"",REGEXREPLACE(LOWER(T4),""\s"", ""%20""),"".png""),1)"),"#REF!") -> #REF! | U3: =IFERROR(__xludf.DUMMYFUNCTION("IMAGE(CONCATENATE(""http://mayumi.fi/boundless/"",REGEXREPLACE(LOWER(U4),""\s"", ""%20""),"".png""),1)"),"#REF!") -> #REF! | V3: =IFERROR(__xludf.DUMMYFUNCTION("IMAGE(CONCATENATE(""http://mayumi.fi/boundless/"",REGEXREPLACE(LOWER(V4),""\s"", ""%20""),"".png""),1)"),"#REF!") -> #REF! | W3: =IFERROR(__xludf.DUMMYFUNCTION("IMAGE(CONCATENATE(""http://mayumi.fi/boundless/"",REGEXREPLACE(LOWER(W4),""\s"", ""%20""),"".png""),1)"),"#REF!") -> #REF! | X3: =IFERROR(__xludf.DUMMYFUNCTION("IMAGE(CONCATENATE(""http://mayumi.fi/boundless/"",REGEXREPLACE(LOWER(X4),""\s"", ""%20""),"".png""),1)"),"#REF!") -> #REF! | Y3: =IFERROR(__xludf.DUMMYFUNCTION("IMAGE(CONCATENATE(""http://mayumi.fi/boundless/"",REGEXREPLACE(LOWER(Y4),""\s"", ""%20""),"".png""),1)"),"#REF!") -> #REF! | Z3: =IFERROR(__xludf.DUMMYFUNCTION("IMAGE(CONCATENATE(""http://mayumi.fi/boundless/"",REGEXREPLACE(LOWER(Z4),""\s"", ""%20""),"".png""),1)"),"#REF!") -> #REF! | AA3: =IFERROR(__xludf.DUMMYFUNCTION("IMAGE(CONCATENATE(""http://mayumi.fi/boundless/"",REGEXREPLACE(LOWER(AA4),""\s"", ""%20""),"".png""),1)"),"#REF!") -> #REF! | AB3: =IFERROR(__xludf.DUMMYFUNCTION("IMAGE(CONCATENATE(""http://mayumi.fi/boundless/"",REGEXREPLACE(LOWER(AB4),""\s"", ""%20""),"".png""),1)"),"#REF!") -> #REF! | AC3: =IFERROR(__xludf.DUMMYFUNCTION("IMAGE(CONCATENATE(""http://mayumi.fi/boundless/"",REGEXREPLACE(LOWER(AC4),""\s"", ""%20""),"".png""),1)"),"#REF!") -> #REF! | AD3: =IFERROR(__xludf.DUMMYFUNCTION("IMAGE(CONCATENATE(""http://mayumi.fi/boundless/"",REGEXREPLACE(LOWER(AD4),""\s"", ""%20""),"".png""),1)"),"#REF!") -> #REF! | AE3: =IFERROR(__xludf.DUMMYFUNCTION("IMAGE(CONCATENATE(""http://mayumi.fi/boundless/"",REGEXREPLACE(LOWER(AE4),""\s"", ""%20""),"".png""),1)"),"#REF!") -> #REF! | AF3: =IFERROR(__xludf.DUMMYFUNCTION("IMAGE(CONCATENATE(""http://mayumi.fi/boundless/"",REGEXREPLACE(LOWER(AF4),""\s"", ""%20""),"".png""),1)"),"#REF!") -> #REF! | AG3: =IFERROR(__xludf.DUMMYFUNCTION("IMAGE(CONCATENATE(""http://mayumi.fi/boundless/"",REGEXREPLACE(LOWER(AG4),""\s"", ""%20""),"".png""),1)"),"#REF!") -> #REF! | AH3: =IFERROR(__xludf.DUMMYFUNCTION("IMAGE(CONCATENATE(""http://mayumi.fi/boundless/"",REGEXREPLACE(LOWER(AH4),""\s"", ""%20""),"".png""),1)"),"#REF!") -> #REF! | AI3: =IFERROR(__xludf.DUMMYFUNCTION("IMAGE(CONCATENATE(""http://mayumi.fi/boundless/"",REGEXREPLACE(LOWER(AI4),""\s"", ""%20""),"".png""),1)"),"#REF!") -> #REF! | AJ3: =IFERROR(__xludf.DUMMYFUNCTION("IMAGE(CONCATENATE(""http://mayumi.fi/boundless/"",REGEXREPLACE(LOWER(AJ4),""\s"", ""%20""),"".png""),1)"),"#REF!") -> #REF! | AK3: =IFERROR(__xludf.DUMMYFUNCTION("IMAGE(CONCATENATE(""http://mayumi.fi/boundless/"",REGEXREPLACE(LOWER(AK4),""\s"", ""%20""),"".png""),1)"),"#REF!") -> #REF! | AL3: =IFERROR(__xludf.DUMMYFUNCTION("IMAGE(CONCATENATE(""http://mayumi.fi/boundless/"",REGEXREPLACE(LOWER(AL4),""\s"", ""%20""),"".png""),1)"),"#REF!") -> #REF! | AM3: =IFERROR(__xludf.DUMMYFUNCTION("IMAGE(CONCATENATE(""http://mayumi.fi/boundless/"",REGEXREPLACE(LOWER(AM4),""\s"", ""%20""),"".png""),1)"),"#REF!") -> #REF! | AN3: =IFERROR(__xludf.DUMMYFUNCTION("IMAGE(CONCATENATE(""http://mayumi.fi/boundless/"",REGEXREPLACE(LOWER(AN4),""\s"", ""%20""),"".png""),1)"),"#REF!") -> #REF! | AO3: =IFERROR(__xludf.DUMMYFUNCTION("IMAGE(CONCATENATE(""http://mayumi.fi/boundless/"",REGEXREPLACE(LOWER(AO4),""\s"", ""%20""),"".png""),1)"),"#REF!") -> #REF! | AP3: =IFERROR(__xludf.DUMMYFUNCTION("IMAGE(CONCATENATE(""http://mayumi.fi/boundless/"",REGEXREPLACE(LOWER(AP4),""\s"", ""%20""),"".png""),1)"),"#REF!") -> #REF! | AQ3: =IFERROR(__xludf.DUMMYFUNCTION("IMAGE(CONCATENATE(""http://mayumi.fi/boundless/"",REGEXREPLACE(LOWER(AQ4),""\s"", ""%20""),"".png""),1)"),"#REF!") -> #REF! | AR3: =IFERROR(__xludf.DUMMYFUNCTION("IMAGE(CONCATENATE(""http://mayumi.fi/boundless/"",REGEXREPLACE(LOWER(AR4),""\s"", ""%20""),"".png""),1)"),"#REF!") -> #REF! | AS3: =IFERROR(__xludf.DUMMYFUNCTION("IMAGE(CONCATENATE(""http://mayumi.fi/boundless/"",REGEXREPLACE(LOWER(AS4),""\s"", ""%20""),"".png""),1)"),"#REF!") -> #REF! | AT3: =IFERROR(__xludf.DUMMYFUNCTION("IMAGE(CONCATENATE(""http://mayumi.fi/boundless/"",REGEXREPLACE(LOWER(AT4),""\s"", ""%20""),"".png""),1)"),"#REF!") -> #REF! | AU3: =IFERROR(__xludf.DUMMYFUNCTION("IMAGE(CONCATENATE(""http://mayumi.fi/boundless/"",REGEXREPLACE(LOWER(AU4),""\s"", ""%20""),"".png""),1)"),"#REF!") -> #REF! | AV3: =IFERROR(__xludf.DUMMYFUNCTION("IMAGE(CONCATENATE(""http://mayumi.fi/boundless/"",REGEXREPLACE(LOWER(AV4),""\s"", ""%20""),"".png""),1)"),"#REF!") -> #REF! | AW3: =IFERROR(__xludf.DUMMYFUNCTION("IMAGE(CONCATENATE(""http://mayumi.fi/boundless/"",REGEXREPLACE(LOWER(AW4),""\s"", ""%20""),"".png""),1)"),"#REF!") -> #REF! | AX3: =IFERROR(__xludf.DUMMYFUNCTION("IMAGE(CONCATENATE(""http://mayumi.fi/boundless/"",REGEXREPLACE(LOWER(AX4),""\s"", ""%20""),"".png""),1)"),"#REF!") -> #REF! | AY3: =IFERROR(__xludf.DUMMYFUNCTION("IMAGE(CONCATENATE(""http://mayumi.fi/boundless/"",REGEXREPLACE(LOWER(AY4),""\s"", ""%20""),"".png""),1)"),"#REF!") -> #REF! | AZ3: =IFERROR(__xludf.DUMMYFUNCTION("IMAGE(CONCATENATE(""http://mayumi.fi/boundless/"",REGEXREPLACE(LOWER(AZ4),""\s"", ""%20""),"".png""),1)"),"#REF!") -> #REF! | BA3: =IFERROR(__xludf.DUMMYFUNCTION("IMAGE(CONCATENATE(""http://mayumi.fi/boundless/"",REGEXREPLACE(LOWER(BA4),""\s"", ""%20""),"".png""),1)"),"#REF!") -> #REF! | BB3: =IFERROR(__xludf.DUMMYFUNCTION("IMAGE(CONCATENATE(""http://mayumi.fi/boundless/"",REGEXREPLACE(LOWER(BB4),""\s"", ""%20""),"".png""),1)"),"#REF!") -> #REF! | BC3: =IFERROR(__xludf.DUMMYFUNCTION("IMAGE(CONCATENATE(""http://mayumi.fi/boundless/"",REGEXREPLACE(LOWER(BC4),""\s"", ""%20""),"".png""),1)"),"#REF!") -> #REF!
A4: =IMAGE("https://forum.playboundless.com/uploads/default/original/3X/2/8/28f5805d5bfa2bc60b86dfe550515ea80ccb02e2.png",4, 50, 50) -> #REF! | B4: Autowant | C4: Want | D4: Total Want | E4: Single | F4: Bulk | G4: Mass | H4: Mass qty | I4: Base Item | K4: Price Each | L4: Spark | M4: Power | N4: Base | O4: Fresh Vital | P4: Ancient Vital | Q4: Pulsating Orb | R4: Vital Orb | S4: Shimmering Orb | T4: Shadow Orb | U4: Reactive Lamella | V4: Glowing Lamella | W4: Hide | X4: Creature Mantle | Y4: Fresh Blood | Z4: Viscous Blood | AA4: Volatile Blood | AB4: Wildstock Eye | AC4: Spitter Eye | AD4: Hopper Eye | AE4: Roadrunner Eye | AF4: Spark Sac | AG4: Thermal Sac | AH4: Flotation Sac | AI4: Adrenal Gland | AJ4: Wildstock Trophy | AK4: Spitter Trophy | AL4: Hopper Trophy | AM4: Cuttletrunk Trophy | AN4: Roadrunner Trophy | AO4: Sulphur Fragment | AP4: Saltpetre Fragment | AQ4: Olivine Fragment | AR4: Cobalt Fragment | AS4: Flint | AT4: Opal | AU4: Petal | AV4: Sap | AW4: Inky Leaf | AX4: Fleshy Leaf | AY4: Spicy Bean | AZ4: Bitter Bean | BA4: Syrup | BB4: Charcoal | BC4: Glass | BE4: Spark | BF4: Power | BG4: =N4 -> Base | BH4: Fresh Vital | BI4: Ancient Vital | BJ4: Pulsating Orb | BK4: Vital Orb | BL4: Shimmering Orb | BM4: Shadow Orb | BN4: Reactive Lamella | BO4: Glowing Lamella | BP4: Hide | BQ4: Creature Mantle | BR4: Fresh Blood | BS4: Viscous Blood | BT4: Volatile Blood | BU4: Spitter Eye | BV4: Wildstock Eye | BW4: Hopper Eye | BX4: Roadrunner Eye | BY4: Adrenal Gland | BZ4: Spark Sac | CA4: Flotation Sac | CB4: Thermal Sac | CC4: Wildstock Trophy | CD4: Cuttletrunk Trophy | CE4: Hopper Trophy | CF4: Spitter Trophy | CG4: Roadrunner Trophy | CH4: Olivine Fragment | CI4: Saltpetre Fragment | CJ4: Sulphur Fragment | CK4: Cobalt Fragment | CL4: Flint | CM4: Opal | CN4: Petal | CO4: Sap | CP4: Inky Leaf | CQ4: Fleshy Leaf | CR4: Spicy Bean | CS4: Bitter Bean | CT4: Syrup | CU4: Charcoal | CV4: Glass | CX4: Fresh Vital | CY4: Ancient Vital | CZ4: Pulsating Orb | DA4: Vital Orb | DB4: Shimmering Orb | DC4: Shadow Orb | DD4: Reactive Lamella | DE4: Glowing Lamella | DF4: Hide | DG4: Creature Mantle | DH4: Fresh Blood | DI4: Viscous Blood | DJ4: Volatile Blood | DK4: Spitter Eye | DL4: Wildstock Eye | DM4: Hopper Eye | DN4: Roadrunner Eye | DO4: Adrenal Gland | DP4: Spark Sac | DQ4: Flotation Sac | DR4: Thermal Sac | DS4: Wildstock Trophy | DT4: Cuttletrunk Trophy | DU4: Hopper Trophy | DV4: Spitter Trophy | DW4: Roadrunner Trophy | DX4: Olivine Fragment | DY4: Saltpetre Fragment | DZ4: Sulphur Fragment | EA4: Cobalt Fragment | EB4: Flint | EC4: Opal | ED4: Petal | EE4: Sap | EF4: Inky Leaf | EG4: Fleshy Leaf | EH4: Spicy Bean | EI4: Bitter Bean | EJ4: Syrup | EK4: Charcoal | EL4: Glass
A5: Compound Base | B5: =IF($C$2,SUMIF(I:I,A5,BG:BG),0) -> 32 | D5: =C5+B5 -> 32 | E5: =IF(ISBLANK(H5),0,IF($C$1,0,CEILING(D5-F5*H5*0.2-G5*H5,1))) -> 2 | F5: =IF(ISBLANK(H5),0,IF($C$1,0,FLOOR((D5-G5*H5)/(H5/5),1))) -> 3 | G5: =IF(ISBLANK(H5),0,IF($C$1,CEILING(D5/H5,1),FLOOR(D5/H5,1))) -> 0 | H5: 50 | J5: =K5*D5 -> 2080 | K5: =CEILING(SUM(CX5:EL5),1)+IF(ISBLANK(I5),0,VLOOKUP(I5,A:K,11,FALSE)) -> 65 | L5: - | M5: - | U5: 1 | BB5: 1 | BC5: 1 | BE5: =IF(ISNUMBER(L5),$G5*L5*25+$F5*L5*10+$E5*L5,0) -> 0 | BF5: =IF(D5>0,M5,0) -> - | BG5: =$G5*N5*IF($H5>50,18,36)+$F5*N5*IF($H5>50,4,8)+$E5*N5 -> 0 | BH5: =$G5*O5*IF($H5>50,18,36)+$F5*O5*IF($H5>50,4,8)+$E5*O5 -> 0 | BI5: =$G5*P5*IF($H5>50,18,36)+$F5*P5*IF($H5>50,4,8)+$E5*P5 -> 0 | BJ5: =$G5*Q5*IF($H5>50,18,36)+$F5*Q5*IF($H5>50,4,8)+$E5*Q5 -> 0 | BK5: =$G5*R5*IF($H5>50,18,36)+$F5*R5*IF($H5>50,4,8)+$E5*R5 -> 0 | BL5: =$G5*S5*IF($H5>50,18,36)+$F5*S5*IF($H5>50,4,8)+$E5*S5 -> 0 | BM5: =$G5*T5*IF($H5>50,18,36)+$F5*T5*IF($H5>50,4,8)+$E5*T5 -> 0 | BN5: =$G5*U5*IF($H5>50,18,36)+$F5*U5*IF($H5>50,4,8)+$E5*U5 -> 26 | ... BT5: =$G5*AA5*IF($H5>50,18,36)+$F5*AA5*IF($H5>50,4,8)+$E5*AA5 -> 0 | BU5: =$G5*AC5*IF($H5>50,18,36)+$F5*AC5*IF($H5>50,4,8)+$E5*AC5 -> 0 | BV5: =$G5*AB5*IF($H5>50,18,36)+$F5*AB5*IF($H5>50,4,8)+$E5*AB5 -> 0 | BW5: =$G5*AD5*IF($H5>50,18,36)+$F5*AD5*IF($H5>50,4,8)+$E5*AD5 -> 0 | BX5: =$G5*AE5*IF($H5>50,18,36)+$F5*AE5*IF($H5>50,4,8)+$E5*AE5 -> 0 | BY5: =$G5*AI5*IF($H5>50,18,36)+$F5*AI5*IF($H5>50,4,8)+$E5*AI5 -> 0 | BZ5: =$G5*AF5*IF($H5>50,18,36)+$F5*AF5*IF($H5>50,4,8)+$E5*AF5 -> 0 | CA5: =$G5*AH5*IF($H5>50,18,36)+$F5*AH5*IF($H5>50,4,8)+$E5*AH5 -> 0 | CB5: =$G5*AG5*IF($H5>50,18,36)+$F5*AG5*IF($H5>50,4,8)+$E5*AG5 -> 0 | CC5: =$G5*AJ5*IF($H5>50,18,36)+$F5*AJ5*IF($H5>50,4,8)+$E5*AJ5 -> 0 | CD5: =$G5*AM5*IF($H5>50,18,36)+$F5*AM5*IF($H5>50,4,8)+$E5*AM5 -> 0 | CE5: =$G5*AL5*IF($H5>50,18,36)+$F5*AL5*IF($H5>50,4,8)+$E5*AL5 -> 0 | CF5: =$G5*AK5*IF($H5>50,18,36)+$F5*AK5*IF($H5>50,4,8)+$E5*AK5 -> 0 | CG5: =$G5*AN5*IF($H5>50,18,36)+$F5*AN5*IF($H5>50,4,8)+$E5*AN5 -> 0 | CH5: =$G5*AQ5*IF($H5>50,18,36)+$F5*AQ5*IF($H5>50,4,8)+$E5*AQ5 -> 0 | CI5: =$G5*AP5*IF($H5>50,18,36)+$F5*AP5*IF($H5>50,4,8)+$E5*AP5 -> 0 | CJ5: =$G5*AO5*IF($H5>50,18,36)+$F5*AO5*IF($H5>50,4,8)+$E5*AO5 -> 0 | CK5: =$G5*AR5*IF($H5>50,18,36)+$F5*AR5*IF($H5>50,4,8)+$E5*AR5 -> 0 | CL5: =$G5*AS5*IF($H5>50,18,36)+$F5*AS5*IF($H5>50,4,8)+$E5*AS5 -> 0 | CM5: =$G5*AT5*IF($H5>50,18,36)+$F5*AT5*IF($H5>50,4,8)+$E5*AT5 -> 0 | CN5: =$G5*AU5*IF($H5>50,18,36)+$F5*AU5*IF($H5>50,4,8)+$E5*AU5 -> 0 | CO5: =$G5*AV5*IF($H5>50,18,36)+$F5*AV5*IF($H5>50,4,8)+$E5*AV5 -> 0 | CP5: =$G5*AW5*IF($H5>50,18,36)+$F5*AW5*IF($H5>50,4,8)+$E5*AW5 -> 0 | CQ5: =$G5*AX5*IF($H5>50,18,36)+$F5*AX5*IF($H5>50,4,8)+$E5*AX5 -> 0 | CR5: =$G5*AY5*IF($H5>50,18,36)+$F5*AY5*IF($H5>50,4,8)+$E5*AY5 -> 0 | ... CV5: =$G5*BC5*IF($H5>50,18,36)+$F5*BC5*IF($H5>50,4,8)+$E5*BC5 -> 26 | CX5: =O5*BH$2/($H5/50)^2 -> 0 | CY5: =P5*BI$2/($H5/50)^2 -> 0 | CZ5: =Q5*BJ$2/($H5/50)^2 -> 0 | DA5: =R5*BK$2/($H5/50)^2 -> 0 | DB5: =S5*BL$2/($H5/50)^2 -> 0 | DC5: =T5*BM$2/($H5/50)^2 -> 0 | DD5: =U5*BN$2/($H5/50)^2 -> 60 | DE5: =V5*BO$2/($H5/50)^2 -> 0 | ... DJ5: =AA5*BT$2/($H5/50)^2 -> 0 | DK5: =AC5*BU$2/($H5/50)^2 -> 0 | DL5: =AB5*BV$2/($H5/50)^2 -> 0 | DM5: =AD5*BW$2/($H5/50)^2 -> 0 | DN5: =AE5*BX$2/($H5/50)^2 -> 0 | DO5: =AI5*BY$2/($H5/50)^2 -> 0 | DP5: =AF5*BZ$2/($H5/50)^2 -> 0 | DQ5: =AH5*CA$2/($H5/50)^2 -> 0 | DR5: =AG5*CB$2/($H5/50)^2 -> 0 | DS5: =AJ5*CC$2/($H5/50)^2 -> 0 | DT5: =AM5*CD$2/($H5/50)^2 -> 0 | DU5: =AL5*CE$2/($H5/50)^2 -> 0 | DV5: =AK5*CF$2/($H5/50)^2 -> 0 | DW5: =AN5*CG$2/($H5/50)^2 -> 0 | DX5: =AQ5*CH$2/($H5/50)^2 -> 0 | DY5: =AP5*CI$2/($H5/50)^2 -> 0 | DZ5: =AO5*CJ$2/($H5/50)^2 -> 0 | EA5: =AR5*CK$2/($H5/50)^2 -> 0 | EB5: =AS5*CL$2/($H5/50)^2 -> 0 | EC5: =AT5*CM$2/($H5/50)^2 -> 0 | ED5: =AU5*CN$2/($H5/50)^2 -> 0 | EE5: =AV5*CO$2/($H5/50)^2 -> 0 | EF5: =AW5*CP$2/($H5/50)^2 -> 0 | EG5: =AX5*CQ$2/($H5/50)^2 -> 0 | EH5: =AY5*CR$2/($H5/50)^2 -> 0 | ... EL5: =BC5*CV$2/($H5/50)^2 -> 4
A6: Paste Base | B6: =IF($C$2,SUMIF(I:I,A6,BG:BG),0) -> 24 | D6: =C6+B6 -> 24 | E6: =IF(ISBLANK(H6),0,IF($C$1,0,CEILING(D6-F6*H6*0.2-G6*H6,1))) -> 4 | F6: =IF(ISBLANK(H6),0,IF($C$1,0,FLOOR((D6-G6*H6)/(H6/5),1))) -> 2 | G6: =IF(ISBLANK(H6),0,IF($C$1,CEILING(D6/H6,1),FLOOR(D6/H6,1))) -> 0 | H6: 50 | J6: =K6*D6 -> 3936 | K6: =CEILING(SUM(CX6:EL6),1)+IF(ISBLANK(I6),0,VLOOKUP(I6,A:K,11,FALSE)) -> 164 | L6: 200 | M6: - | AY6: 2 | AZ6: 1 | BC6: 1 | BE6: =IF(ISNUMBER(L6),$G6*L6*25+$F6*L6*10+$E6*L6,0) -> 4800 | BF6: =IF(D6>0,M6,0) -> - | BG6: =$G6*N6*IF($H6>50,18,36)+$F6*N6*IF($H6>50,4,8)+$E6*N6 -> 0 | BH6: =$G6*O6*IF($H6>50,18,36)+$F6*O6*IF($H6>50,4,8)+$E6*O6 -> 0 | BI6: =$G6*P6*IF($H6>50,18,36)+$F6*P6*IF($H6>50,4,8)+$E6*P6 -> 0 | BJ6: =$G6*Q6*IF($H6>50,18,36)+$F6*Q6*IF($H6>50,4,8)+$E6*Q6 -> 0 | BK6: =$G6*R6*IF($H6>50,18,36)+$F6*R6*IF($H6>50,4,8)+$E6*R6 -> 0 | BL6: =$G6*S6*IF($H6>50,18,36)+$F6*S6*IF($H6>50,4,8)+$E6*S6 -> 0 | BM6: =$G6*T6*IF($H6>50,18,36)+$F6*T6*IF($H6>50,4,8)+$E6*T6 -> 0 | BN6: =$G6*U6*IF($H6>50,18,36)+$F6*U6*IF($H6>50,4,8)+$E6*U6 -> 0 | ... BT6: =$G6*AA6*IF($H6>50,18,36)+$F6*AA6*IF($H6>50,4,8)+$E6*AA6 -> 0 | BU6: =$G6*AC6*IF($H6>50,18,36)+$F6*AC6*IF($H6>50,4,8)+$E6*AC6 -> 0 | BV6: =$G6*AB6*IF($H6>50,18,36)+$F6*AB6*IF($H6>50,4,8)+$E6*AB6 -> 0 | BW6: =$G6*AD6*IF($H6>50,18,36)+$F6*AD6*IF($H6>50,4,8)+$E6*AD6 -> 0 | BX6: =$G6*AE6*IF($H6>50,18,36)+$F6*AE6*IF($H6>50,4,8)+$E6*AE6 -> 0 | BY6: =$G6*AI6*IF($H6>50,18,36)+$F6*AI6*IF($H6>50,4,8)+$E6*AI6 -> 0 | BZ6: =$G6*AF6*IF($H6>50,18,36)+$F6*AF6*IF($H6>50,4,8)+$E6*AF6 -> 0 | CA6: =$G6*AH6*IF($H6>50,18,36)+$F6*AH6*IF($H6>50,4,8)+$E6*AH6 -> 0 | CB6: =$G6*AG6*IF($H6>50,18,36)+$F6*AG6*IF($H6>50,4,8)+$E6*AG6 -> 0 | CC6: =$G6*AJ6*IF($H6>50,18,36)+$F6*AJ6*IF($H6>50,4,8)+$E6*AJ6 -> 0 | CD6: =$G6*AM6*IF($H6>50,18,36)+$F6*AM6*IF($H6>50,4,8)+$E6*AM6 -> 0 | CE6: =$G6*AL6*IF($H6>50,18,36)+$F6*AL6*IF($H6>50,4,8)+$E6*AL6 -> 0 | CF6: =$G6*AK6*IF($H6>50,18,36)+$F6*AK6*IF($H6>50,4,8)+$E6*AK6 -> 0 | CG6: =$G6*AN6*IF($H6>50,18,36)+$F6*AN6*IF($H6>50,4,8)+$E6*AN6 -> 0 | CH6: =$G6*AQ6*IF($H6>50,18,36)+$F6*AQ6*IF($H6>50,4,8)+$E6*AQ6 -> 0 | CI6: =$G6*AP6*IF($H6>50,18,36)+$F6*AP6*IF($H6>50,4,8)+$E6*AP6 -> 0 | CJ6: =$G6*AO6*IF($H6>50,18,36)+$F6*AO6*IF($H6>50,4,8)+$E6*AO6 -> 0 | CK6: =$G6*AR6*IF($H6>50,18,36)+$F6*AR6*IF($H6>50,4,8)+$E6*AR6 -> 0 | CL6: =$G6*AS6*IF($H6>50,18,36)+$F6*AS6*IF($H6>50,4,8)+$E6*AS6 -> 0 | CM6: =$G6*AT6*IF($H6>50,18,36)+$F6*AT6*IF($H6>50,4,8)+$E6*AT6 -> 0 | CN6: =$G6*AU6*IF($H6>50,18,36)+$F6*AU6*IF($H6>50,4,8)+$E6*AU6 -> 0 | CO6: =$G6*AV6*IF($H6>50,18,36)+$F6*AV6*IF($H6>50,4,8)+$E6*AV6 -> 0 | CP6: =$G6*AW6*IF($H6>50,18,36)+$F6*AW6*IF($H6>50,4,8)+$E6*AW6 -> 0 | CQ6: =$G6*AX6*IF($H6>50,18,36)+$F6*AX6*IF($H6>50,4,8)+$E6*AX6 -> 0 | CR6: =$G6*AY6*IF($H6>50,18,36)+$F6*AY6*IF($H6>50,4,8)+$E6*AY6 -> 40 | ... CV6: =$G6*BC6*IF($H6>50,18,36)+$F6*BC6*IF($H6>50,4,8)+$E6*BC6 -> 20 | CX6: =O6*BH$2/($H6/50)^2 -> 0 | CY6: =P6*BI$2/($H6/50)^2 -> 0 | CZ6: =Q6*BJ$2/($H6/50)^2 -> 0 | DA6: =R6*BK$2/($H6/50)^2 -> 0 | DB6: =S6*BL$2/($H6/50)^2 -> 0 | DC6: =T6*BM$2/($H6/50)^2 -> 0 | DD6: =U6*BN$2/($H6/50)^2 -> 0 | DE6: =V6*BO$2/($H6/50)^2 -> 0 | ... DJ6: =AA6*BT$2/($H6/50)^2 -> 0 | DK6: =AC6*BU$2/($H6/50)^2 -> 0 | DL6: =AB6*BV$2/($H6/50)^2 -> 0 | DM6: =AD6*BW$2/($H6/50)^2 -> 0 | DN6: =AE6*BX$2/($H6/50)^2 -> 0 | DO6: =AI6*BY$2/($H6/50)^2 -> 0 | DP6: =AF6*BZ$2/($H6/50)^2 -> 0 | DQ6: =AH6*CA$2/($H6/50)^2 -> 0 | DR6: =AG6*CB$2/($H6/50)^2 -> 0 | DS6: =AJ6*CC$2/($H6/50)^2 -> 0 | DT6: =AM6*CD$2/($H6/50)^2 -> 0 | DU6: =AL6*CE$2/($H6/50)^2 -> 0 | DV6: =AK6*CF$2/($H6/50)^2 -> 0 | DW6: =AN6*CG$2/($H6/50)^2 -> 0 | DX6: =AQ6*CH$2/($H6/50)^2 -> 0 | DY6: =AP6*CI$2/($H6/50)^2 -> 0 | DZ6: =AO6*CJ$2/($H6/50)^2 -> 0 | EA6: =AR6*CK$2/($H6/50)^2 -> 0 | EB6: =AS6*CL$2/($H6/50)^2 -> 0 | EC6: =AT6*CM$2/($H6/50)^2 -> 0 | ED6: =AU6*CN$2/($H6/50)^2 -> 0 | EE6: =AV6*CO$2/($H6/50)^2 -> 0 | EF6: =AW6*CP$2/($H6/50)^2 -> 0 | EG6: =AX6*CQ$2/($H6/50)^2 -> 0 | EH6: =AY6*CR$2/($H6/50)^2 -> 70 | ... EL6: =BC6*CV$2/($H6/50)^2 -> 4
A7: Gum Base | B7: =IF($C$2,SUMIF(I:I,A7,BG:BG),0) -> 28 | D7: =C7+B7 -> 28 | E7: =IF(ISBLANK(H7),0,IF($C$1,0,CEILING(D7-F7*H7*0.2-G7*H7,1))) -> 8 | F7: =IF(ISBLANK(H7),0,IF($C$1,0,FLOOR((D7-G7*H7)/(H7/5),1))) -> 2 | G7: =IF(ISBLANK(H7),0,IF($C$1,CEILING(D7/H7,1),FLOOR(D7/H7,1))) -> 0 | H7: 50 | J7: =K7*D7 -> 336 | K7: =CEILING(SUM(CX7:EL7),1)+IF(ISBLANK(I7),0,VLOOKUP(I7,A:K,11,FALSE)) -> 12 | L7: - | M7: - | AX7: 1 | BA7: 1 | BC7: 1 | BE7: =IF(ISNUMBER(L7),$G7*L7*25+$F7*L7*10+$E7*L7,0) -> 0 | BF7: =IF(D7>0,M7,0) -> - | BG7: =$G7*N7*IF($H7>50,18,36)+$F7*N7*IF($H7>50,4,8)+$E7*N7 -> 0 | BH7: =$G7*O7*IF($H7>50,18,36)+$F7*O7*IF($H7>50,4,8)+$E7*O7 -> 0 | BI7: =$G7*P7*IF($H7>50,18,36)+$F7*P7*IF($H7>50,4,8)+$E7*P7 -> 0 | BJ7: =$G7*Q7*IF($H7>50,18,36)+$F7*Q7*IF($H7>50,4,8)+$E7*Q7 -> 0 | BK7: =$G7*R7*IF($H7>50,18,36)+$F7*R7*IF($H7>50,4,8)+$E7*R7 -> 0 | BL7: =$G7*S7*IF($H7>50,18,36)+$F7*S7*IF($H7>50,4,8)+$E7*S7 -> 0 | BM7: =$G7*T7*IF($H7>50,18,36)+$F7*T7*IF($H7>50,4,8)+$E7*T7 -> 0 | BN7: =$G7*U7*IF($H7>50,18,36)+$F7*U7*IF($H7>50,4,8)+$E7*U7 -> 0 | ... BT7: =$G7*AA7*IF($H7>50,18,36)+$F7*AA7*IF($H7>50,4,8)+$E7*AA7 -> 0 | BU7: =$G7*AC7*IF($H7>50,18,36)+$F7*AC7*IF($H7>50,4,8)+$E7*AC7 -> 0 | BV7: =$G7*AB7*IF($H7>50,18,36)+$F7*AB7*IF($H7>50,4,8)+$E7*AB7 -> 0 | BW7: =$G7*AD7*IF($H7>50,18,36)+$F7*AD7*IF($H7>50,4,8)+$E7*AD7 -> 0 | BX7: =$G7*AE7*IF($H7>50,18,36)+$F7*AE7*IF($H7>50,4,8)+$E7*AE7 -> 0 | BY7: =$G7*AI7*IF($H7>50,18,36)+$F7*AI7*IF($H7>50,4,8)+$E7*AI7 -> 0 | BZ7: =$G7*AF7*IF($H7>50,18,36)+$F7*AF7*IF($H7>50,4,8)+$E7*AF7 -> 0 | CA7: =$G7*AH7*IF($H7>50,18,36)+$F7*AH7*IF($H7>50,4,8)+$E7*AH7 -> 0 | CB7: =$G7*AG7*IF($H7>50,18,36)+$F7*AG7*IF($H7>50,4,8)+$E7*AG7 -> 0 | CC7: =$G7*AJ7*IF($H7>50,18,36)+$F7*AJ7*IF($H7>50,4,8)+$E7*AJ7 -> 0 | CD7: =$G7*AM7*IF($H7>50,18,36)+$F7*AM7*IF($H7>50,4,8)+$E7*AM7 -> 0 | CE7: =$G7*AL7*IF($H7>50,18,36)+$F7*AL7*IF($H7>50,4,8)+$E7*AL7 -> 0 | CF7: =$G7*AK7*IF($H7>50,18,36)+$F7*AK7*IF($H7>50,4,8)+$E7*AK7 -> 0 | CG7: =$G7*AN7*IF($H7>50,18,36)+$F7*AN7*IF($H7>50,4,8)+$E7*AN7 -> 0 | CH7: =$G7*AQ7*IF($H7>50,18,36)+$F7*AQ7*IF($H7>50,4,8)+$E7*AQ7 -> 0 | CI7: =$G7*AP7*IF($H7>50,18,36)+$F7*AP7*IF($H7>50,4,8)+$E7*AP7 -> 0 | CJ7: =$G7*AO7*IF($H7>50,18,36)+$F7*AO7*IF($H7>50,4,8)+$E7*AO7 -> 0 | CK7: =$G7*AR7*IF($H7>50,18,36)+$F7*AR7*IF($H7>50,4,8)+$E7*AR7 -> 0 | CL7: =$G7*AS7*IF($H7>50,18,36)+$F7*AS7*IF($H7>50,4,8)+$E7*AS7 -> 0 | CM7: =$G7*AT7*IF($H7>50,18,36)+$F7*AT7*IF($H7>50,4,8)+$E7*AT7 -> 0 | CN7: =$G7*AU7*IF($H7>50,18,36)+$F7*AU7*IF($H7>50,4,8)+$E7*AU7 -> 0 | CO7: =$G7*AV7*IF($H7>50,18,36)+$F7*AV7*IF($H7>50,4,8)+$E7*AV7 -> 0 | CP7: =$G7*AW7*IF($H7>50,18,36)+$F7*AW7*IF($H7>50,4,8)+$E7*AW7 -> 0 | CQ7: =$G7*AX7*IF($H7>50,18,36)+$F7*AX7*IF($H7>50,4,8)+$E7*AX7 -> 24 | CR7: =$G7*AY7*IF($H7>50,18,36)+$F7*AY7*IF($H7>50,4,8)+$E7*AY7 -> 0 | ... CV7: =$G7*BC7*IF($H7>50,18,36)+$F7*BC7*IF($H7>50,4,8)+$E7*BC7 -> 24 | CX7: =O7*BH$2/($H7/50)^2 -> 0 | CY7: =P7*BI$2/($H7/50)^2 -> 0 | CZ7: =Q7*BJ$2/($H7/50)^2 -> 0 | DA7: =R7*BK$2/($H7/50)^2 -> 0 | DB7: =S7*BL$2/($H7/50)^2 -> 0 | DC7: =T7*BM$2/($H7/50)^2 -> 0 | DD7: =U7*BN$2/($H7/50)^2 -> 0 | DE7: =V7*BO$2/($H7/50)^2 -> 0 | ... DJ7: =AA7*BT$2/($H7/50)^2 -> 0 | DK7: =AC7*BU$2/($H7/50)^2 -> 0 | DL7: =AB7*BV$2/($H7/50)^2 -> 0 | DM7: =AD7*BW$2/($H7/50)^2 -> 0 | DN7: =AE7*BX$2/($H7/50)^2 -> 0 | DO7: =AI7*BY$2/($H7/50)^2 -> 0 | DP7: =AF7*BZ$2/($H7/50)^2 -> 0 | DQ7: =AH7*CA$2/($H7/50)^2 -> 0 | DR7: =AG7*CB$2/($H7/50)^2 -> 0 | DS7: =AJ7*CC$2/($H7/50)^2 -> 0 | DT7: =AM7*CD$2/($H7/50)^2 -> 0 | DU7: =AL7*CE$2/($H7/50)^2 -> 0 | DV7: =AK7*CF$2/($H7/50)^2 -> 0 | DW7: =AN7*CG$2/($H7/50)^2 -> 0 | DX7: =AQ7*CH$2/($H7/50)^2 -> 0 | DY7: =AP7*CI$2/($H7/50)^2 -> 0 | DZ7: =AO7*CJ$2/($H7/50)^2 -> 0 | EA7: =AR7*CK$2/($H7/50)^2 -> 0 | EB7: =AS7*CL$2/($H7/50)^2 -> 0 | EC7: =AT7*CM$2/($H7/50)^2 -> 0 | ED7: =AU7*CN$2/($H7/50)^2 -> 0 | EE7: =AV7*CO$2/($H7/50)^2 -> 0 | EF7: =AW7*CP$2/($H7/50)^2 -> 0 | EG7: =AX7*CQ$2/($H7/50)^2 -> 4 | EH7: =AY7*CR$2/($H7/50)^2 -> 0 | ... EL7: =BC7*CV$2/($H7/50)^2 -> 4
A8: Catalyst Base | B8: =IF($C$2,SUMIF(I:I,A8,BG:BG),0) -> 28 | D8: =C8+B8 -> 28 | E8: =IF(ISBLANK(H8),0,IF($C$1,0,CEILING(D8-F8*H8*0.2-G8*H8,1))) -> 8 | F8: =IF(ISBLANK(H8),0,IF($C$1,0,FLOOR((D8-G8*H8)/(H8/5),1))) -> 2 | G8: =IF(ISBLANK(H8),0,IF($C$1,CEILING(D8/H8,1),FLOOR(D8/H8,1))) -> 0 | H8: 50 | J8: =K8*D8 -> 1652 | K8: =CEILING(SUM(CX8:EL8),1)+IF(ISBLANK(I8),0,VLOOKUP(I8,A:K,11,FALSE)) -> 59 | L8: 200 | M8: - | AR8: 1 | AW8: 2 | BC8: 1 | BE8: =IF(ISNUMBER(L8),$G8*L8*25+$F8*L8*10+$E8*L8,0) -> 5600 | BF8: =IF(D8>0,M8,0) -> - | BG8: =$G8*N8*IF($H8>50,18,36)+$F8*N8*IF($H8>50,4,8)+$E8*N8 -> 0 | BH8: =$G8*O8*IF($H8>50,18,36)+$F8*O8*IF($H8>50,4,8)+$E8*O8 -> 0 | BI8: =$G8*P8*IF($H8>50,18,36)+$F8*P8*IF($H8>50,4,8)+$E8*P8 -> 0 | BJ8: =$G8*Q8*IF($H8>50,18,36)+$F8*Q8*IF($H8>50,4,8)+$E8*Q8 -> 0 | BK8: =$G8*R8*IF($H8>50,18,36)+$F8*R8*IF($H8>50,4,8)+$E8*R8 -> 0 | BL8: =$G8*S8*IF($H8>50,18,36)+$F8*S8*IF($H8>50,4,8)+$E8*S8 -> 0 | BM8: =$G8*T8*IF($H8>50,18,36)+$F8*T8*IF($H8>50,4,8)+$E8*T8 -> 0 | BN8: =$G8*U8*IF($H8>50,18,36)+$F8*U8*IF($H8>50,4,8)+$E8*U8 -> 0 | ... BT8: =$G8*AA8*IF($H8>50,18,36)+$F8*AA8*IF($H8>50,4,8)+$E8*AA8 -> 0 | BU8: =$G8*AC8*IF($H8>50,18,36)+$F8*AC8*IF($H8>50,4,8)+$E8*AC8 -> 0 | BV8: =$G8*AB8*IF($H8>50,18,36)+$F8*AB8*IF($H8>50,4,8)+$E8*AB8 -> 0 | BW8: =$G8*AD8*IF($H8>50,18,36)+$F8*AD8*IF($H8>50,4,8)+$E8*AD8 -> 0 | BX8: =$G8*AE8*IF($H8>50,18,36)+$F8*AE8*IF($H8>50,4,8)+$E8*AE8 -> 0 | BY8: =$G8*AI8*IF($H8>50,18,36)+$F8*AI8*IF($H8>50,4,8)+$E8*AI8 -> 0 | BZ8: =$G8*AF8*IF($H8>50,18,36)+$F8*AF8*IF($H8>50,4,8)+$E8*AF8 -> 0 | CA8: =$G8*AH8*IF($H8>50,18,36)+$F8*AH8*IF($H8>50,4,8)+$E8*AH8 -> 0 | CB8: =$G8*AG8*IF($H8>50,18,36)+$F8*AG8*IF($H8>50,4,8)+$E8*AG8 -> 0 | CC8: =$G8*AJ8*IF($H8>50,18,36)+$F8*AJ8*IF($H8>50,4,8)+$E8*AJ8 -> 0 | CD8: =$G8*AM8*IF($H8>50,18,36)+$F8*AM8*IF($H8>50,4,8)+$E8*AM8 -> 0 | CE8: =$G8*AL8*IF($H8>50,18,36)+$F8*AL8*IF($H8>50,4,8)+$E8*AL8 -> 0 | CF8: =$G8*AK8*IF($H8>50,18,36)+$F8*AK8*IF($H8>50,4,8)+$E8*AK8 -> 0 | CG8: =$G8*AN8*IF($H8>50,18,36)+$F8*AN8*IF($H8>50,4,8)+$E8*AN8 -> 0 | CH8: =$G8*AQ8*IF($H8>50,18,36)+$F8*AQ8*IF($H8>50,4,8)+$E8*AQ8 -> 0 | CI8: =$G8*AP8*IF($H8>50,18,36)+$F8*AP8*IF($H8>50,4,8)+$E8*AP8 -> 0 | CJ8: =$G8*AO8*IF($H8>50,18,36)+$F8*AO8*IF($H8>50,4,8)+$E8*AO8 -> 0 | CK8: =$G8*AR8*IF($H8>50,18,36)+$F8*AR8*IF($H8>50,4,8)+$E8*AR8 -> 24 | CL8: =$G8*AS8*IF($H8>50,18,36)+$F8*AS8*IF($H8>50,4,8)+$E8*AS8 -> 0 | CM8: =$G8*AT8*IF($H8>50,18,36)+$F8*AT8*IF($H8>50,4,8)+$E8*AT8 -> 0 | CN8: =$G8*AU8*IF($H8>50,18,36)+$F8*AU8*IF($H8>50,4,8)+$E8*AU8 -> 0 | CO8: =$G8*AV8*IF($H8>50,18,36)+$F8*AV8*IF($H8>50,4,8)+$E8*AV8 -> 0 | CP8: =$G8*AW8*IF($H8>50,18,36)+$F8*AW8*IF($H8>50,4,8)+$E8*AW8 -> 48 | CQ8: =$G8*AX8*IF($H8>50,18,36)+$F8*AX8*IF($H8>50,4,8)+$E8*AX8 -> 0 | CR8: =$G8*AY8*IF($H8>50,18,36)+$F8*AY8*IF($H8>50,4,8)+$E8*AY8 -> 0 | ... CV8: =$G8*BC8*IF($H8>50,18,36)+$F8*BC8*IF($H8>50,4,8)+$E8*BC8 -> 24 | CX8: =O8*BH$2/($H8/50)^2 -> 0 | CY8: =P8*BI$2/($H8/50)^2 -> 0 | CZ8: =Q8*BJ$2/($H8/50)^2 -> 0 | DA8: =R8*BK$2/($H8/50)^2 -> 0 | DB8: =S8*BL$2/($H8/50)^2 -> 0 | DC8: =T8*BM$2/($H8/50)^2 -> 0 | DD8: =U8*BN$2/($H8/50)^2 -> 0 | DE8: =V8*BO$2/($H8/50)^2 -> 0 | ... DJ8: =AA8*BT$2/($H8/50)^2 -> 0 | DK8: =AC8*BU$2/($H8/50)^2 -> 0 | DL8: =AB8*BV$2/($H8/50)^2 -> 0 | DM8: =AD8*BW$2/($H8/50)^2 -> 0 | DN8: =AE8*BX$2/($H8/50)^2 -> 0 | DO8: =AI8*BY$2/($H8/50)^2 -> 0 | DP8: =AF8*BZ$2/($H8/50)^2 -> 0 | DQ8: =AH8*CA$2/($H8/50)^2 -> 0 | DR8: =AG8*CB$2/($H8/50)^2 -> 0 | DS8: =AJ8*CC$2/($H8/50)^2 -> 0 | DT8: =AM8*CD$2/($H8/50)^2 -> 0 | DU8: =AL8*CE$2/($H8/50)^2 -> 0 | DV8: =AK8*CF$2/($H8/50)^2 -> 0 | DW8: =AN8*CG$2/($H8/50)^2 -> 0 | DX8: =AQ8*CH$2/($H8/50)^2 -> 0 | DY8: =AP8*CI$2/($H8/50)^2 -> 0 | DZ8: =AO8*CJ$2/($H8/50)^2 -> 0 | EA8: =AR8*CK$2/($H8/50)^2 -> 15 | EB8: =AS8*CL$2/($H8/50)^2 -> 0 | EC8: =AT8*CM$2/($H8/50)^2 -> 0 | ED8: =AU8*CN$2/($H8/50)^2 -> 0 | EE8: =AV8*CO$2/($H8/50)^2 -> 0 | EF8: =AW8*CP$2/($H8/50)^2 -> 40 | EG8: =AX8*CQ$2/($H8/50)^2 -> 0 | EH8: =AY8*CR$2/($H8/50)^2 -> 0 | ... EL8: =BC8*CV$2/($H8/50)^2 -> 4
A9: Solvent Base | B9: =IF($C$2,SUMIF(I:I,A9,BG:BG),0) -> 0 | D9: =C9+B9 -> 0 | E9: =IF(ISBLANK(H9),0,IF($C$1,0,CEILING(D9-F9*H9*0.2-G9*H9,1))) -> 0 | F9: =IF(ISBLANK(H9),0,IF($C$1,0,FLOOR((D9-G9*H9)/(H9/5),1))) -> 0 | G9: =IF(ISBLANK(H9),0,IF($C$1,CEILING(D9/H9,1),FLOOR(D9/H9,1))) -> 0 | H9: 50 | J9: =K9*D9 -> 0 | K9: =CEILING(SUM(CX9:EL9),1)+IF(ISBLANK(I9),0,VLOOKUP(I9,A:K,11,FALSE)) -> 37 | L9: 200 | M9: - | Z9: 1 | AQ9: 1 | BC9: 1 | BE9: =IF(ISNUMBER(L9),$G9*L9*25+$F9*L9*10+$E9*L9,0) -> 0 | BF9: =IF(D9>0,M9,0) -> 0 | BG9: =$G9*N9*IF($H9>50,18,36)+$F9*N9*IF($H9>50,4,8)+$E9*N9 -> 0 | BH9: =$G9*O9*IF($H9>50,18,36)+$F9*O9*IF($H9>50,4,8)+$E9*O9 -> 0 | BI9: =$G9*P9*IF($H9>50,18,36)+$F9*P9*IF($H9>50,4,8)+$E9*P9 -> 0 | BJ9: =$G9*Q9*IF($H9>50,18,36)+$F9*Q9*IF($H9>50,4,8)+$E9*Q9 -> 0 | BK9: =$G9*R9*IF($H9>50,18,36)+$F9*R9*IF($H9>50,4,8)+$E9*R9 -> 0 | BL9: =$G9*S9*IF($H9>50,18,36)+$F9*S9*IF($H9>50,4,8)+$E9*S9 -> 0 | BM9: =$G9*T9*IF($H9>50,18,36)+$F9*T9*IF($H9>50,4,8)+$E9*T9 -> 0 | BN9: =$G9*U9*IF($H9>50,18,36)+$F9*U9*IF($H9>50,4,8)+$E9*U9 -> 0 | ... BT9: =$G9*AA9*IF($H9>50,18,36)+$F9*AA9*IF($H9>50,4,8)+$E9*AA9 -> 0 | BU9: =$G9*AC9*IF($H9>50,18,36)+$F9*AC9*IF($H9>50,4,8)+$E9*AC9 -> 0 | BV9: =$G9*AB9*IF($H9>50,18,36)+$F9*AB9*IF($H9>50,4,8)+$E9*AB9 -> 0 | BW9: =$G9*AD9*IF($H9>50,18,36)+$F9*AD9*IF($H9>50,4,8)+$E9*AD9 -> 0 | BX9: =$G9*AE9*IF($H9>50,18,36)+$F9*AE9*IF($H9>50,4,8)+$E9*AE9 -> 0 | BY9: =$G9*AI9*IF($H9>50,18,36)+$F9*AI9*IF($H9>50,4,8)+$E9*AI9 -> 0 | BZ9: =$G9*AF9*IF($H9>50,18,36)+$F9*AF9*IF($H9>50,4,8)+$E9*AF9 -> 0 | CA9: =$G9*AH9*IF($H9>50,18,36)+$F9*AH9*IF($H9>50,4,8)+$E9*AH9 -> 0 | CB9: =$G9*AG9*IF($H9>50,18,36)+$F9*AG9*IF($H9>50,4,8)+$E9*AG9 -> 0 | CC9: =$G9*AJ9*IF($H9>50,18,36)+$F9*AJ9*IF($H9>50,4,8)+$E9*AJ9 -> 0 | CD9: =$G9*AM9*IF($H9>50,18,36)+$F9*AM9*IF($H9>50,4,8)+$E9*AM9 -> 0 | CE9: =$G9*AL9*IF($H9>50,18,36)+$F9*AL9*IF($H9>50,4,8)+$E9*AL9 -> 0 | CF9: =$G9*AK9*IF($H9>50,18,36)+$F9*AK9*IF($H9>50,4,8)+$E9*AK9 -> 0 | CG9: =$G9*AN9*IF($H9>50,18,36)+$F9*AN9*IF($H9>50,4,8)+$E9*AN9 -> 0 | CH9: =$G9*AQ9*IF($H9>50,18,36)+$F9*AQ9*IF($H9>50,4,8)+$E9*AQ9 -> 0 | CI9: =$G9*AP9*IF($H9>50,18,36)+$F9*AP9*IF($H9>50,4,8)+$E9*AP9 -> 0 | CJ9: =$G9*AO9*IF($H9>50,18,36)+$F9*AO9*IF($H9>50,4,8)+$E9*AO9 -> 0 | CK9: =$G9*AR9*IF($H9>50,18,36)+$F9*AR9*IF($H9>50,4,8)+$E9*AR9 -> 0 | CL9: =$G9*AS9*IF($H9>50,18,36)+$F9*AS9*IF($H9>50,4,8)+$E9*AS9 -> 0 | CM9: =$G9*AT9*IF($H9>50,18,36)+$F9*AT9*IF($H9>50,4,8)+$E9*AT9 -> 0 | CN9: =$G9*AU9*IF($H9>50,18,36)+$F9*AU9*IF($H9>50,4,8)+$E9*AU9 -> 0 | CO9: =$G9*AV9*IF($H9>50,18,36)+$F9*AV9*IF($H9>50,4,8)+$E9*AV9 -> 0 | CP9: =$G9*AW9*IF($H9>50,18,36)+$F9*AW9*IF($H9>50,4,8)+$E9*AW9 -> 0 | CQ9: =$G9*AX9*IF($H9>50,18,36)+$F9*AX9*IF($H9>50,4,8)+$E9*AX9 -> 0 | CR9: =$G9*AY9*IF($H9>50,18,36)+$F9*AY9*IF($H9>50,4,8)+$E9*AY9 -> 0 | ... CV9: =$G9*BC9*IF($H9>50,18,36)+$F9*BC9*IF($H9>50,4,8)+$E9*BC9 -> 0 | CX9: =O9*BH$2/($H9/50)^2 -> 0 | CY9: =P9*BI$2/($H9/50)^2 -> 0 | CZ9: =Q9*BJ$2/($H9/50)^2 -> 0 | DA9: =R9*BK$2/($H9/50)^2 -> 0 | DB9: =S9*BL$2/($H9/50)^2 -> 0 | DC9: =T9*BM$2/($H9/50)^2 -> 0 | DD9: =U9*BN$2/($H9/50)^2 -> 0 | DE9: =V9*BO$2/($H9/50)^2 -> 0 | ... DJ9: =AA9*BT$2/($H9/50)^2 -> 0 | DK9: =AC9*BU$2/($H9/50)^2 -> 0 | DL9: =AB9*BV$2/($H9/50)^2 -> 0 | DM9: =AD9*BW$2/($H9/50)^2 -> 0 | DN9: =AE9*BX$2/($H9/50)^2 -> 0 | DO9: =AI9*BY$2/($H9/50)^2 -> 0 | DP9: =AF9*BZ$2/($H9/50)^2 -> 0 | DQ9: =AH9*CA$2/($H9/50)^2 -> 0 | DR9: =AG9*CB$2/($H9/50)^2 -> 0 | DS9: =AJ9*CC$2/($H9/50)^2 -> 0 | DT9: =AM9*CD$2/($H9/50)^2 -> 0 | DU9: =AL9*CE$2/($H9/50)^2 -> 0 | DV9: =AK9*CF$2/($H9/50)^2 -> 0 | DW9: =AN9*CG$2/($H9/50)^2 -> 0 | DX9: =AQ9*CH$2/($H9/50)^2 -> 30 | DY9: =AP9*CI$2/($H9/50)^2 -> 0 | DZ9: =AO9*CJ$2/($H9/50)^2 -> 0 | EA9: =AR9*CK$2/($H9/50)^2 -> 0 | EB9: =AS9*CL$2/($H9/50)^2 -> 0 | EC9: =AT9*CM$2/($H9/50)^2 -> 0 | ED9: =AU9*CN$2/($H9/50)^2 -> 0 | EE9: =AV9*CO$2/($H9/50)^2 -> 0 | EF9: =AW9*CP$2/($H9/50)^2 -> 0 | EG9: =AX9*CQ$2/($H9/50)^2 -> 0 | EH9: =AY9*CR$2/($H9/50)^2 -> 0 | ... EL9: =BC9*CV$2/($H9/50)^2 -> 4
A10: Resin Base | B10: =IF($C$2,SUMIF(I:I,A10,BG:BG),0) -> 61 | D10: =C10+B10 -> 61 | E10: =IF(ISBLANK(H10),0,IF($C$1,0,CEILING(D10-F10*H10*0.2-G10*H10,1))) -> 1 | F10: =IF(ISBLANK(H10),0,IF($C$1,0,FLOOR((D10-G10*H10)/(H10/5),1))) -> 1 | G10: =IF(ISBLANK(H10),0,IF($C$1,CEILING(D10/H10,1),FLOOR(D10/H10,1))) -> 1 | H10: 50 | J10: =K10*D10 -> 793 | K10: =CEILING(SUM(CX10:EL10),1)+IF(ISBLANK(I10),0,VLOOKUP(I10,A:K,11,FALSE)) -> 13 | L10: - | M10: - | P10: 1 | AV10: 1 | BC10: 1 | BE10: =IF(ISNUMBER(L10),$G10*L10*25+$F10*L10*10+$E10*L10,0) -> 0 | BF10: =IF(D10>0,M10,0) -> - | BG10: =$G10*N10*IF($H10>50,18,36)+$F10*N10*IF($H10>50,4,8)+$E10*N10 -> 0 | BH10: =$G10*O10*IF($H10>50,18,36)+$F10*O10*IF($H10>50,4,8)+$E10*O10 -> 0 | BI10: =$G10*P10*IF($H10>50,18,36)+$F10*P10*IF($H10>50,4,8)+$E10*P10 -> 45 | BJ10: =$G10*Q10*IF($H10>50,18,36)+$F10*Q10*IF($H10>50,4,8)+$E10*Q10 -> 0 | BK10: =$G10*R10*IF($H10>50,18,36)+$F10*R10*IF($H10>50,4,8)+$E10*R10 -> 0 | BL10: =$G10*S10*IF($H10>50,18,36)+$F10*S10*IF($H10>50,4,8)+$E10*S10 -> 0 | BM10: =$G10*T10*IF($H10>50,18,36)+$F10*T10*IF($H10>50,4,8)+$E10*T10 -> 0 | BN10: =$G10*U10*IF($H10>50,18,36)+$F10*U10*IF($H10>50,4,8)+$E10*U10 -> 0 | ... BT10: =$G10*AA10*IF($H10>50,18,36)+$F10*AA10*IF($H10>50,4,8)+$E10*AA10 -> 0 | BU10: =$G10*AC10*IF($H10>50,18,36)+$F10*AC10*IF($H10>50,4,8)+$E10*AC10 -> 0 | BV10: =$G10*AB10*IF($H10>50,18,36)+$F10*AB10*IF($H10>50,4,8)+$E10*AB10 -> 0 | BW10: =$G10*AD10*IF($H10>50,18,36)+$F10*AD10*IF($H10>50,4,8)+$E10*AD10 -> 0 | BX10: =$G10*AE10*IF($H10>50,18,36)+$F10*AE10*IF($H10>50,4,8)+$E10*AE10 -> 0 | BY10: =$G10*AI10*IF($H10>50,18,36)+$F10*AI10*IF($H10>50,4,8)+$E10*AI10 -> 0 | BZ10: =$G10*AF10*IF($H10>50,18,36)+$F10*AF10*IF($H10>50,4,8)+$E10*AF10 -> 0 | CA10: =$G10*AH10*IF($H10>50,18,36)+$F10*AH10*IF($H10>50,4,8)+$E10*AH10 -> 0 | CB10: =$G10*AG10*IF($H10>50,18,36)+$F10*AG10*IF($H10>50,4,8)+$E10*AG10 -> 0 | CC10: =$G10*AJ10*IF($H10>50,18,36)+$F10*AJ10*IF($H10>50,4,8)+$E10*AJ10 -> 0 | CD10: =$G10*AM10*IF($H10>50,18,36)+$F10*AM10*IF($H10>50,4,8)+$E10*AM10 -> 0 | CE10: =$G10*AL10*IF($H10>50,18,36)+$F10*AL10*IF($H10>50,4,8)+$E10*AL10 -> 0 | CF10: =$G10*AK10*IF($H10>50,18,36)+$F10*AK10*IF($H10>50,4,8)+$E10*AK10 -> 0 | CG10: =$G10*AN10*IF($H10>50,18,36)+$F10*AN10*IF($H10>50,4,8)+$E10*AN10 -> 0 | CH10: =$G10*AQ10*IF($H10>50,18,36)+$F10*AQ10*IF($H10>50,4,8)+$E10*AQ10 -> 0 | CI10: =$G10*AP10*IF($H10>50,18,36)+$F10*AP10*IF($H10>50,4,8)+$E10*AP10 -> 0 | CJ10: =$G10*AO10*IF($H10>50,18,36)+$F10*AO10*IF($H10>50,4,8)+$E10*AO10 -> 0 | CK10: =$G10*AR10*IF($H10>50,18,36)+$F10*AR10*IF($H10>50,4,8)+$E10*AR10 -> 0 | CL10: =$G10*AS10*IF($H10>50,18,36)+$F10*AS10*IF($H10>50,4,8)+$E10*AS10 -> 0 | CM10: =$G10*AT10*IF($H10>50,18,36)+$F10*AT10*IF($H10>50,4,8)+$E10*AT10 -> 0 | CN10: =$G10*AU10*IF($H10>50,18,36)+$F10*AU10*IF($H10>50,4,8)+$E10*AU10 -> 0 | CO10: =$G10*AV10*IF($H10>50,18,36)+$F10*AV10*IF($H10>50,4,8)+$E10*AV10 -> 45 | CP10: =$G10*AW10*IF($H10>50,18,36)+$F10*AW10*IF($H10>50,4,8)+$E10*AW10 -> 0 | CQ10: =$G10*AX10*IF($H10>50,18,36)+$F10*AX10*IF($H10>50,4,8)+$E10*AX10 -> 0 | CR10: =$G10*AY10*IF($H10>50,18,36)+$F10*AY10*IF($H10>50,4,8)+$E10*AY10 -> 0 | ... CV10: =$G10*BC10*IF($H10>50,18,36)+$F10*BC10*IF($H10>50,4,8)+$E10*BC10 -> 45 | CX10: =O10*BH$2/($H10/50)^2 -> 0 | CY10: =P10*BI$2/($H10/50)^2 -> 3 | CZ10: =Q10*BJ$2/($H10/50)^2 -> 0 | DA10: =R10*BK$2/($H10/50)^2 -> 0 | DB10: =S10*BL$2/($H10/50)^2 -> 0 | DC10: =T10*BM$2/($H10/50)^2 -> 0 | DD10: =U10*BN$2/($H10/50)^2 -> 0 | DE10: =V10*BO$2/($H10/50)^2 -> 0 | ... DJ10: =AA10*BT$2/($H10/50)^2 -> 0 | DK10: =AC10*BU$2/($H10/50)^2 -> 0 | DL10: =AB10*BV$2/($H10/50)^2 -> 0 | DM10: =AD10*BW$2/($H10/50)^2 -> 0 | DN10: =AE10*BX$2/($H10/50)^2 -> 0 | DO10: =AI10*BY$2/($H10/50)^2 -> 0 | DP10: =AF10*BZ$2/($H10/50)^2 -> 0 | DQ10: =AH10*CA$2/($H10/50)^2 -> 0 | DR10: =AG10*CB$2/($H10/50)^2 -> 0 | DS10: =AJ10*CC$2/($H10/50)^2 -> 0 | DT10: =AM10*CD$2/($H10/50)^2 -> 0 | DU10: =AL10*CE$2/($H10/50)^2 -> 0 | DV10: =AK10*CF$2/($H10/50)^2 -> 0 | DW10: =AN10*CG$2/($H10/50)^2 -> 0 | DX10: =AQ10*CH$2/($H10/50)^2 -> 0 | DY10: =AP10*CI$2/($H10/50)^2 -> 0 | DZ10: =AO10*CJ$2/($H10/50)^2 -> 0 | EA10: =AR10*CK$2/($H10/50)^2 -> 0 | EB10: =AS10*CL$2/($H10/50)^2 -> 0 | EC10: =AT10*CM$2/($H10/50)^2 -> 0 | ED10: =AU10*CN$2/($H10/50)^2 -> 0 | EE10: =AV10*CO$2/($H10/50)^2 -> 6 | EF10: =AW10*CP$2/($H10/50)^2 -> 0 | EG10: =AX10*CQ$2/($H10/50)^2 -> 0 | EH10: =AY10*CR$2/($H10/50)^2 -> 0 | ... EL10: =BC10*CV$2/($H10/50)^2 -> 4
A11: Special Gum | B11: =IF($C$2,SUMIF(I:I,A11,BG:BG),0) -> 0 | C11: 15 | D11: =C11+B11 -> 15 | E11: =IF(ISBLANK(H11),0,IF($C$1,0,CEILING(D11-F11*H11*0.2-G11*H11,1))) -> 15 | F11: =IF(ISBLANK(H11),0,IF($C$1,0,FLOOR((D11-G11*H11)/(H11/5),1))) -> 0 | G11: =IF(ISBLANK(H11),0,IF($C$1,CEILING(D11/H11,1),FLOOR(D11/H11,1))) -> 0 | H11: 100 | I11: =$A$7 -> Gum Base | J11: =K11*D11 -> 195 | K11: =CEILING(SUM(CX11:EL11),1)+IF(ISBLANK(I11),0,VLOOKUP(I11,A:K,11,FALSE)) -> 13 | L11: - | M11: - | N11: 1 | Z11: 1 | BE11: =IF(ISNUMBER(L11),$G11*L11*25+$F11*L11*10+$E11*L11,0) -> 0 | BF11: =IF(D11>0,M11,0) -> - | BG11: =$G11*N11*IF($H11>50,18,36)+$F11*N11*IF($H11>50,4,8)+$E11*N11 -> 15 | BH11: =$G11*O11*IF($H11>50,18,36)+$F11*O11*IF($H11>50,4,8)+$E11*O11 -> 0 | BI11: =$G11*P11*IF($H11>50,18,36)+$F11*P11*IF($H11>50,4,8)+$E11*P11 -> 0 | BJ11: =$G11*Q11*IF($H11>50,18,36)+$F11*Q11*IF($H11>50,4,8)+$E11*Q11 -> 0 | BK11: =$G11*R11*IF($H11>50,18,36)+$F11*R11*IF($H11>50,4,8)+$E11*R11 -> 0 | BL11: =$G11*S11*IF($H11>50,18,36)+$F11*S11*IF($H11>50,4,8)+$E11*S11 -> 0 | BM11: =$G11*T11*IF($H11>50,18,36)+$F11*T11*IF($H11>50,4,8)+$E11*T11 -> 0 | BN11: =$G11*U11*IF($H11>50,18,36)+$F11*U11*IF($H11>50,4,8)+$E11*U11 -> 0 | ... BT11: =$G11*AA11*IF($H11>50,18,36)+$F11*AA11*IF($H11>50,4,8)+$E11*AA11 -> 0 | BU11: =$G11*AC11*IF($H11>50,18,36)+$F11*AC11*IF($H11>50,4,8)+$E11*AC11 -> 0 | BV11: =$G11*AB11*IF($H11>50,18,36)+$F11*AB11*IF($H11>50,4,8)+$E11*AB11 -> 0 | BW11: =$G11*AD11*IF($H11>50,18,36)+$F11*AD11*IF($H11>50,4,8)+$E11*AD11 -> 0 | BX11: =$G11*AE11*IF($H11>50,18,36)+$F11*AE11*IF($H11>50,4,8)+$E11*AE11 -> 0 | BY11: =$G11*AI11*IF($H11>50,18,36)+$F11*AI11*IF($H11>50,4,8)+$E11*AI11 -> 0 | BZ11: =$G11*AF11*IF($H11>50,18,36)+$F11*AF11*IF($H11>50,4,8)+$E11*AF11 -> 0 | CA11: =$G11*AH11*IF($H11>50,18,36)+$F11*AH11*IF($H11>50,4,8)+$E11*AH11 -> 0 | CB11: =$G11*AG11*IF($H11>50,18,36)+$F11*AG11*IF($H11>50,4,8)+$E11*AG11 -> 0 | CC11: =$G11*AJ11*IF($H11>50,18,36)+$F11*AJ11*IF($H11>50,4,8)+$E11*AJ11 -> 0 | CD11: =$G11*AM11*IF($H11>50,18,36)+$F11*AM11*IF($H11>50,4,8)+$E11*AM11 -> 0 | CE11: =$G11*AL11*IF($H11>50,18,36)+$F11*AL11*IF($H11>50,4,8)+$E11*AL11 -> 0 | CF11: =$G11*AK11*IF($H11>50,18,36)+$F11*AK11*IF($H11>50,4,8)+$E11*AK11 -> 0 | CG11: =$G11*AN11*IF($H11>50,18,36)+$F11*AN11*IF($H11>50,4,8)+$E11*AN11 -> 0 | CH11: =$G11*AQ11*IF($H11>50,18,36)+$F11*AQ11*IF($H11>50,4,8)+$E11*AQ11 -> 0 | CI11: =$G11*AP11*IF($H11>50,18,36)+$F11*AP11*IF($H11>50,4,8)+$E11*AP11 -> 0 | CJ11: =$G11*AO11*IF($H11>50,18,36)+$F11*AO11*IF($H11>50,4,8)+$E11*AO11 -> 0 | CK11: =$G11*AR11*IF($H11>50,18,36)+$F11*AR11*IF($H11>50,4,8)+$E11*AR11 -> 0 | CL11: =$G11*AS11*IF($H11>50,18,36)+$F11*AS11*IF($H11>50,4,8)+$E11*AS11 -> 0 | CM11: =$G11*AT11*IF($H11>50,18,36)+$F11*AT11*IF($H11>50,4,8)+$E11*AT11 -> 0 | CN11: =$G11*AU11*IF($H11>50,18,36)+$F11*AU11*IF($H11>50,4,8)+$E11*AU11 -> 0 | CO11: =$G11*AV11*IF($H11>50,18,36)+$F11*AV11*IF($H11>50,4,8)+$E11*AV11 -> 0 | CP11: =$G11*AW11*IF($H11>50,18,36)+$F11*AW11*IF($H11>50,4,8)+$E11*AW11 -> 0 | CQ11: =$G11*AX11*IF($H11>50,18,36)+$F11*AX11*IF($H11>50,4,8)+$E11*AX11 -> 0 | CR11: =$G11*AY11*IF($H11>50,18,36)+$F11*AY11*IF($H11>50,4,8)+$E11*AY11 -> 0 | ... CV11: =$G11*BC11*IF($H11>50,18,36)+$F11*BC11*IF($H11>50,4,8)+$E11*BC11 -> 0 | CX11: =O11*BH$2/($H11/50)^2 -> 0 | CY11: =P11*BI$2/($H11/50)^2 -> 0 | CZ11: =Q11*BJ$2/($H11/50)^2 -> 0 | DA11: =R11*BK$2/($H11/50)^2 -> 0 | DB11: =S11*BL$2/($H11/50)^2 -> 0 | DC11: =T11*BM$2/($H11/50)^2 -> 0 | DD11: =U11*BN$2/($H11/50)^2 -> 0 | DE11: =V11*BO$2/($H11/50)^2 -> 0 | ... DJ11: =AA11*BT$2/($H11/50)^2 -> 0 | DK11: =AC11*BU$2/($H11/50)^2 -> 0 | DL11: =AB11*BV$2/($H11/50)^2 -> 0 | DM11: =AD11*BW$2/($H11/50)^2 -> 0 | DN11: =AE11*BX$2/($H11/50)^2 -> 0 | DO11: =AI11*BY$2/($H11/50)^2 -> 0 | DP11: =AF11*BZ$2/($H11/50)^2 -> 0 | DQ11: =AH11*CA$2/($H11/50)^2 -> 0 | DR11: =AG11*CB$2/($H11/50)^2 -> 0 | DS11: =AJ11*CC$2/($H11/50)^2 -> 0 | DT11: =AM11*CD$2/($H11/50)^2 -> 0 | DU11: =AL11*CE$2/($H11/50)^2 -> 0 | DV11: =AK11*CF$2/($H11/50)^2 -> 0 | DW11: =AN11*CG$2/($H11/50)^2 -> 0 | DX11: =AQ11*CH$2/($H11/50)^2 -> 0 | DY11: =AP11*CI$2/($H11/50)^2 -> 0 | DZ11: =AO11*CJ$2/($H11/50)^2 -> 0 | EA11: =AR11*CK$2/($H11/50)^2 -> 0 | EB11: =AS11*CL$2/($H11/50)^2 -> 0 | EC11: =AT11*CM$2/($H11/50)^2 -> 0 | ED11: =AU11*CN$2/($H11/50)^2 -> 0 | EE11: =AV11*CO$2/($H11/50)^2 -> 0 | EF11: =AW11*CP$2/($H11/50)^2 -> 0 | EG11: =AX11*CQ$2/($H11/50)^2 -> 0 | EH11: =AY11*CR$2/($H11/50)^2 -> 0 | ... EL11: =BC11*CV$2/($H11/50)^2 -> 0
A12: Effect Gum | B12: =IF($C$2,SUMIF(I:I,A12,BG:BG),0) -> 0 | C12: 10 | D12: =C12+B12 -> 10 | E12: =IF(ISBLANK(H12),0,IF($C$1,0,CEILING(D12-F12*H12*0.2-G12*H12,1))) -> 10 | F12: =IF(ISBLANK(H12),0,IF($C$1,0,FLOOR((D12-G12*H12)/(H12/5),1))) -> 0 | G12: =IF(ISBLANK(H12),0,IF($C$1,CEILING(D12/H12,1),FLOOR(D12/H12,1))) -> 0 | H12: 100 | I12: =$A$7 -> Gum Base | J12: =K12*D12 -> 220 | K12: =CEILING(SUM(CX12:EL12),1)+IF(ISBLANK(I12),0,VLOOKUP(I12,A:K,11,FALSE)) -> 22 | L12: - | M12: - | N12: 1 | AG12: 1 | BE12: =IF(ISNUMBER(L12),$G12*L12*25+$F12*L12*10+$E12*L12,0) -> 0 | BF12: =IF(D12>0,M12,0) -> - | BG12: =$G12*N12*IF($H12>50,18,36)+$F12*N12*IF($H12>50,4,8)+$E12*N12 -> 10 | BH12: =$G12*O12*IF($H12>50,18,36)+$F12*O12*IF($H12>50,4,8)+$E12*O12 -> 0 | BI12: =$G12*P12*IF($H12>50,18,36)+$F12*P12*IF($H12>50,4,8)+$E12*P12 -> 0 | BJ12: =$G12*Q12*IF($H12>50,18,36)+$F12*Q12*IF($H12>50,4,8)+$E12*Q12 -> 0 | BK12: =$G12*R12*IF($H12>50,18,36)+$F12*R12*IF($H12>50,4,8)+$E12*R12 -> 0 | BL12: =$G12*S12*IF($H12>50,18,36)+$F12*S12*IF($H12>50,4,8)+$E12*S12 -> 0 | BM12: =$G12*T12*IF($H12>50,18,36)+$F12*T12*IF($H12>50,4,8)+$E12*T12 -> 0 | BN12: =$G12*U12*IF($H12>50,18,36)+$F12*U12*IF($H12>50,4,8)+$E12*U12 -> 0 | ... BT12: =$G12*AA12*IF($H12>50,18,36)+$F12*AA12*IF($H12>50,4,8)+$E12*AA12 -> 0 | BU12: =$G12*AC12*IF($H12>50,18,36)+$F12*AC12*IF($H12>50,4,8)+$E12*AC12 -> 0 | BV12: =$G12*AB12*IF($H12>50,18,36)+$F12*AB12*IF($H12>50,4,8)+$E12*AB12 -> 0 | BW12: =$G12*AD12*IF($H12>50,18,36)+$F12*AD12*IF($H12>50,4,8)+$E12*AD12 -> 0 | BX12: =$G12*AE12*IF($H12>50,18,36)+$F12*AE12*IF($H12>50,4,8)+$E12*AE12 -> 0 | BY12: =$G12*AI12*IF($H12>50,18,36)+$F12*AI12*IF($H12>50,4,8)+$E12*AI12 -> 0 | BZ12: =$G12*AF12*IF($H12>50,18,36)+$F12*AF12*IF($H12>50,4,8)+$E12*AF12 -> 0 | CA12: =$G12*AH12*IF($H12>50,18,36)+$F12*AH12*IF($H12>50,4,8)+$E12*AH12 -> 0 | CB12: =$G12*AG12*IF($H12>50,18,36)+$F12*AG12*IF($H12>50,4,8)+$E12*AG12 -> 10 | CC12: =$G12*AJ12*IF($H12>50,18,36)+$F12*AJ12*IF($H12>50,4,8)+$E12*AJ12 -> 0 | CD12: =$G12*AM12*IF($H12>50,18,36)+$F12*AM12*IF($H12>50,4,8)+$E12*AM12 -> 0 | CE12: =$G12*AL12*IF($H12>50,18,36)+$F12*AL12*IF($H12>50,4,8)+$E12*AL12 -> 0 | CF12: =$G12*AK12*IF($H12>50,18,36)+$F12*AK12*IF($H12>50,4,8)+$E12*AK12 -> 0 | CG12: =$G12*AN12*IF($H12>50,18,36)+$F12*AN12*IF($H12>50,4,8)+$E12*AN12 -> 0 | CH12: =$G12*AQ12*IF($H12>50,18,36)+$F12*AQ12*IF($H12>50,4,8)+$E12*AQ12 -> 0 | CI12: =$G12*AP12*IF($H12>50,18,36)+$F12*AP12*IF($H12>50,4,8)+$E12*AP12 -> 0 | CJ12: =$G12*AO12*IF($H12>50,18,36)+$F12*AO12*IF($H12>50,4,8)+$E12*AO12 -> 0 | CK12: =$G12*AR12*IF($H12>50,18,36)+$F12*AR12*IF($H12>50,4,8)+$E12*AR12 -> 0 | CL12: =$G12*AS12*IF($H12>50,18,36)+$F12*AS12*IF($H12>50,4,8)+$E12*AS12 -> 0 | CM12: =$G12*AT12*IF($H12>50,18,36)+$F12*AT12*IF($H12>50,4,8)+$E12*AT12 -> 0 | CN12: =$G12*AU12*IF($H12>50,18,36)+$F12*AU12*IF($H12>50,4,8)+$E12*AU12 -> 0 | CO12: =$G12*AV12*IF($H12>50,18,36)+$F12*AV12*IF($H12>50,4,8)+$E12*AV12 -> 0 | CP12: =$G12*AW12*IF($H12>50,18,36)+$F12*AW12*IF($H12>50,4,8)+$E12*AW12 -> 0 | CQ12: =$G12*AX12*IF($H12>50,18,36)+$F12*AX12*IF($H12>50,4,8)+$E12*AX12 -> 0 | CR12: =$G12*AY12*IF($H12>50,18,36)+$F12*AY12*IF($H12>50,4,8)+$E12*AY12 -> 0 | ... CV12: =$G12*BC12*IF($H12>50,18,36)+$F12*BC12*IF($H12>50,4,8)+$E12*BC12 -> 0 | CX12: =O12*BH$2/($H12/50)^2 -> 0 | CY12: =P12*BI$2/($H12/50)^2 -> 0 | CZ12: =Q12*BJ$2/($H12/50)^2 -> 0 | DA12: =R12*BK$2/($H12/50)^2 -> 0 | DB12: =S12*BL$2/($H12/50)^2 -> 0 | DC12: =T12*BM$2/($H12/50)^2 -> 0 | DD12: =U12*BN$2/($H12/50)^2 -> 0 | DE12: =V12*BO$2/($H12/50)^2 -> 0 | ... DJ12: =AA12*BT$2/($H12/50)^2 -> 0 | DK12: =AC12*BU$2/($H12/50)^2 -> 0 | DL12: =AB12*BV$2/($H12/50)^2 -> 0 | DM12: =AD12*BW$2/($H12/50)^2 -> 0 | DN12: =AE12*BX$2/($H12/50)^2 -> 0 | DO12: =AI12*BY$2/($H12/50)^2 -> 0 | DP12: =AF12*BZ$2/($H12/50)^2 -> 0 | DQ12: =AH12*CA$2/($H12/50)^2 -> 0 | DR12: =AG12*CB$2/($H12/50)^2 -> 10 | DS12: =AJ12*CC$2/($H12/50)^2 -> 0 | DT12: =AM12*CD$2/($H12/50)^2 -> 0 | DU12: =AL12*CE$2/($H12/50)^2 -> 0 | DV12: =AK12*CF$2/($H12/50)^2 -> 0 | DW12: =AN12*CG$2/($H12/50)^2 -> 0 | DX12: =AQ12*CH$2/($H12/50)^2 -> 0 | DY12: =AP12*CI$2/($H12/50)^2 -> 0 | DZ12: =AO12*CJ$2/($H12/50)^2 -> 0 | EA12: =AR12*CK$2/($H12/50)^2 -> 0 | EB12: =AS12*CL$2/($H12/50)^2 -> 0 | EC12: =AT12*CM$2/($H12/50)^2 -> 0 | ED12: =AU12*CN$2/($H12/50)^2 -> 0 | EE12: =AV12*CO$2/($H12/50)^2 -> 0 | EF12: =AW12*CP$2/($H12/50)^2 -> 0 | EG12: =AX12*CQ$2/($H12/50)^2 -> 0 | EH12: =AY12*CR$2/($H12/50)^2 -> 0 | ... EL12: =BC12*CV$2/($H12/50)^2 -> 0
A13: Longevity Gum | B13: =IF($C$2,SUMIF(I:I,A13,BG:BG),0) -> 0 | D13: =C13+B13 -> 0 | E13: =IF(ISBLANK(H13),0,IF($C$1,0,CEILING(D13-F13*H13*0.2-G13*H13,1))) -> 0 | F13: =IF(ISBLANK(H13),0,IF($C$1,0,FLOOR((D13-G13*H13)/(H13/5),1))) -> 0 | G13: =IF(ISBLANK(H13),0,IF($C$1,CEILING(D13/H13,1),FLOOR(D13/H13,1))) -> 0 | H13: 100 | I13: =$A$7 -> Gum Base | J13: =K13*D13 -> 0 | K13: =CEILING(SUM(CX13:EL13),1)+IF(ISBLANK(I13),0,VLOOKUP(I13,A:K,11,FALSE)) -> 13 | L13: - | M13: - | N13: 1 | X13: 1 | BE13: =IF(ISNUMBER(L13),$G13*L13*25+$F13*L13*10+$E13*L13,0) -> 0 | BF13: =IF(D13>0,M13,0) -> 0 | BG13: =$G13*N13*IF($H13>50,18,36)+$F13*N13*IF($H13>50,4,8)+$E13*N13 -> 0 | BH13: =$G13*O13*IF($H13>50,18,36)+$F13*O13*IF($H13>50,4,8)+$E13*O13 -> 0 | BI13: =$G13*P13*IF($H13>50,18,36)+$F13*P13*IF($H13>50,4,8)+$E13*P13 -> 0 | BJ13: =$G13*Q13*IF($H13>50,18,36)+$F13*Q13*IF($H13>50,4,8)+$E13*Q13 -> 0 | BK13: =$G13*R13*IF($H13>50,18,36)+$F13*R13*IF($H13>50,4,8)+$E13*R13 -> 0 | BL13: =$G13*S13*IF($H13>50,18,36)+$F13*S13*IF($H13>50,4,8)+$E13*S13 -> 0 | BM13: =$G13*T13*IF($H13>50,18,36)+$F13*T13*IF($H13>50,4,8)+$E13*T13 -> 0 | BN13: =$G13*U13*IF($H13>50,18,36)+$F13*U13*IF($H13>50,4,8)+$E13*U13 -> 0 | ... BT13: =$G13*AA13*IF($H13>50,18,36)+$F13*AA13*IF($H13>50,4,8)+$E13*AA13 -> 0 | BU13: =$G13*AC13*IF($H13>50,18,36)+$F13*AC13*IF($H13>50,4,8)+$E13*AC13 -> 0 | BV13: =$G13*AB13*IF($H13>50,18,36)+$F13*AB13*IF($H13>50,4,8)+$E13*AB13 -> 0 | BW13: =$G13*AD13*IF($H13>50,18,36)+$F13*AD13*IF($H13>50,4,8)+$E13*AD13 -> 0 | BX13: =$G13*AE13*IF($H13>50,18,36)+$F13*AE13*IF($H13>50,4,8)+$E13*AE13 -> 0 | BY13: =$G13*AI13*IF($H13>50,18,36)+$F13*AI13*IF($H13>50,4,8)+$E13*AI13 -> 0 | BZ13: =$G13*AF13*IF($H13>50,18,36)+$F13*AF13*IF($H13>50,4,8)+$E13*AF13 -> 0 | CA13: =$G13*AH13*IF($H13>50,18,36)+$F13*AH13*IF($H13>50,4,8)+$E13*AH13 -> 0 | CB13: =$G13*AG13*IF($H13>50,18,36)+$F13*AG13*IF($H13>50,4,8)+$E13*AG13 -> 0 | CC13: =$G13*AJ13*IF($H13>50,18,36)+$F13*AJ13*IF($H13>50,4,8)+$E13*AJ13 -> 0 | CD13: =$G13*AM13*IF($H13>50,18,36)+$F13*AM13*IF($H13>50,4,8)+$E13*AM13 -> 0 | CE13: =$G13*AL13*IF($H13>50,18,36)+$F13*AL13*IF($H13>50,4,8)+$E13*AL13 -> 0 | CF13: =$G13*AK13*IF($H13>50,18,36)+$F13*AK13*IF($H13>50,4,8)+$E13*AK13 -> 0 | CG13: =$G13*AN13*IF($H13>50,18,36)+$F13*AN13*IF($H13>50,4,8)+$E13*AN13 -> 0 | CH13: =$G13*AQ13*IF($H13>50,18,36)+$F13*AQ13*IF($H13>50,4,8)+$E13*AQ13 -> 0 | CI13: =$G13*AP13*IF($H13>50,18,36)+$F13*AP13*IF($H13>50,4,8)+$E13*AP13 -> 0 | CJ13: =$G13*AO13*IF($H13>50,18,36)+$F13*AO13*IF($H13>50,4,8)+$E13*AO13 -> 0 | CK13: =$G13*AR13*IF($H13>50,18,36)+$F13*AR13*IF($H13>50,4,8)+$E13*AR13 -> 0 | CL13: =$G13*AS13*IF($H13>50,18,36)+$F13*AS13*IF($H13>50,4,8)+$E13*AS13 -> 0 | CM13: =$G13*AT13*IF($H13>50,18,36)+$F13*AT13*IF($H13>50,4,8)+$E13*AT13 -> 0 | CN13: =$G13*AU13*IF($H13>50,18,36)+$F13*AU13*IF($H13>50,4,8)+$E13*AU13 -> 0 | CO13: =$G13*AV13*IF($H13>50,18,36)+$F13*AV13*IF($H13>50,4,8)+$E13*AV13 -> 0 | CP13: =$G13*AW13*IF($H13>50,18,36)+$F13*AW13*IF($H13>50,4,8)+$E13*AW13 -> 0 | CQ13: =$G13*AX13*IF($H13>50,18,36)+$F13*AX13*IF($H13>50,4,8)+$E13*AX13 -> 0 | CR13: =$G13*AY13*IF($H13>50,18,36)+$F13*AY13*IF($H13>50,4,8)+$E13*AY13 -> 0 | ... CV13: =$G13*BC13*IF($H13>50,18,36)+$F13*BC13*IF($H13>50,4,8)+$E13*BC13 -> 0 | CX13: =O13*BH$2/($H13/50)^2 -> 0 | CY13: =P13*BI$2/($H13/50)^2 -> 0 | CZ13: =Q13*BJ$2/($H13/50)^2 -> 0 | DA13: =R13*BK$2/($H13/50)^2 -> 0 | DB13: =S13*BL$2/($H13/50)^2 -> 0 | DC13: =T13*BM$2/($H13/50)^2 -> 0 | DD13: =U13*BN$2/($H13/50)^2 -> 0 | DE13: =V13*BO$2/($H13/50)^2 -> 0 | ... DJ13: =AA13*BT$2/($H13/50)^2 -> 0 | DK13: =AC13*BU$2/($H13/50)^2 -> 0 | DL13: =AB13*BV$2/($H13/50)^2 -> 0 | DM13: =AD13*BW$2/($H13/50)^2 -> 0 | DN13: =AE13*BX$2/($H13/50)^2 -> 0 | DO13: =AI13*BY$2/($H13/50)^2 -> 0 | DP13: =AF13*BZ$2/($H13/50)^2 -> 0 | DQ13: =AH13*CA$2/($H13/50)^2 -> 0 | DR13: =AG13*CB$2/($H13/50)^2 -> 0 | DS13: =AJ13*CC$2/($H13/50)^2 -> 0 | DT13: =AM13*CD$2/($H13/50)^2 -> 0 | DU13: =AL13*CE$2/($H13/50)^2 -> 0 | DV13: =AK13*CF$2/($H13/50)^2 -> 0 | DW13: =AN13*CG$2/($H13/50)^2 -> 0 | DX13: =AQ13*CH$2/($H13/50)^2 -> 0 | DY13: =AP13*CI$2/($H13/50)^2 -> 0 | DZ13: =AO13*CJ$2/($H13/50)^2 -> 0 | EA13: =AR13*CK$2/($H13/50)^2 -> 0 | EB13: =AS13*CL$2/($H13/50)^2 -> 0 | EC13: =AT13*CM$2/($H13/50)^2 -> 0 | ED13: =AU13*CN$2/($H13/50)^2 -> 0 | EE13: =AV13*CO$2/($H13/50)^2 -> 0 | EF13: =AW13*CP$2/($H13/50)^2 -> 0 | EG13: =AX13*CQ$2/($H13/50)^2 -> 0 | EH13: =AY13*CR$2/($H13/50)^2 -> 0 | ... EL13: =BC13*CV$2/($H13/50)^2 -> 0
A14: Ease Gum | B14: =IF($C$2,SUMIF(I:I,A14,BG:BG),0) -> 0 | D14: =C14+B14 -> 0 | E14: =IF(ISBLANK(H14),0,IF($C$1,0,CEILING(D14-F14*H14*0.2-G14*H14,1))) -> 0 | F14: =IF(ISBLANK(H14),0,IF($C$1,0,FLOOR((D14-G14*H14)/(H14/5),1))) -> 0 | G14: =IF(ISBLANK(H14),0,IF($C$1,CEILING(D14/H14,1),FLOOR(D14/H14,1))) -> 0 | H14: 100 | I14: =$A$7 -> Gum Base | J14: =K14*D14 -> 0 | K14: =CEILING(SUM(CX14:EL14),1)+IF(ISBLANK(I14),0,VLOOKUP(I14,A:K,11,FALSE)) -> 13 | L14: - | M14: - | N14: 1 | Y14: 1 | BE14: =IF(ISNUMBER(L14),$G14*L14*25+$F14*L14*10+$E14*L14,0) -> 0 | BF14: =IF(D14>0,M14,0) -> 0 | BG14: =$G14*N14*IF($H14>50,18,36)+$F14*N14*IF($H14>50,4,8)+$E14*N14 -> 0 | BH14: =$G14*O14*IF($H14>50,18,36)+$F14*O14*IF($H14>50,4,8)+$E14*O14 -> 0 | BI14: =$G14*P14*IF($H14>50,18,36)+$F14*P14*IF($H14>50,4,8)+$E14*P14 -> 0 | BJ14: =$G14*Q14*IF($H14>50,18,36)+$F14*Q14*IF($H14>50,4,8)+$E14*Q14 -> 0 | BK14: =$G14*R14*IF($H14>50,18,36)+$F14*R14*IF($H14>50,4,8)+$E14*R14 -> 0 | BL14: =$G14*S14*IF($H14>50,18,36)+$F14*S14*IF($H14>50,4,8)+$E14*S14 -> 0 | BM14: =$G14*T14*IF($H14>50,18,36)+$F14*T14*IF($H14>50,4,8)+$E14*T14 -> 0 | BN14: =$G14*U14*IF($H14>50,18,36)+$F14*U14*IF($H14>50,4,8)+$E14*U14 -> 0 | ... BT14: =$G14*AA14*IF($H14>50,18,36)+$F14*AA14*IF($H14>50,4,8)+$E14*AA14 -> 0 | BU14: =$G14*AC14*IF($H14>50,18,36)+$F14*AC14*IF($H14>50,4,8)+$E14*AC14 -> 0 | BV14: =$G14*AB14*IF($H14>50,18,36)+$F14*AB14*IF($H14>50,4,8)+$E14*AB14 -> 0 | BW14: =$G14*AD14*IF($H14>50,18,36)+$F14*AD14*IF($H14>50,4,8)+$E14*AD14 -> 0 | BX14: =$G14*AE14*IF($H14>50,18,36)+$F14*AE14*IF($H14>50,4,8)+$E14*AE14 -> 0 | BY14: =$G14*AI14*IF($H14>50,18,36)+$F14*AI14*IF($H14>50,4,8)+$E14*AI14 -> 0 | BZ14: =$G14*AF14*IF($H14>50,18,36)+$F14*AF14*IF($H14>50,4,8)+$E14*AF14 -> 0 | CA14: =$G14*AH14*IF($H14>50,18,36)+$F14*AH14*IF($H14>50,4,8)+$E14*AH14 -> 0 | CB14: =$G14*AG14*IF($H14>50,18,36)+$F14*AG14*IF($H14>50,4,8)+$E14*AG14 -> 0 | CC14: =$G14*AJ14*IF($H14>50,18,36)+$F14*AJ14*IF($H14>50,4,8)+$E14*AJ14 -> 0 | CD14: =$G14*AM14*IF($H14>50,18,36)+$F14*AM14*IF($H14>50,4,8)+$E14*AM14 -> 0 | CE14: =$G14*AL14*IF($H14>50,18,36)+$F14*AL14*IF($H14>50,4,8)+$E14*AL14 -> 0 | CF14: =$G14*AK14*IF($H14>50,18,36)+$F14*AK14*IF($H14>50,4,8)+$E14*AK14 -> 0 | CG14: =$G14*AN14*IF($H14>50,18,36)+$F14*AN14*IF($H14>50,4,8)+$E14*AN14 -> 0 | CH14: =$G14*AQ14*IF($H14>50,18,36)+$F14*AQ14*IF($H14>50,4,8)+$E14*AQ14 -> 0 | CI14: =$G14*AP14*IF($H14>50,18,36)+$F14*AP14*IF($H14>50,4,8)+$E14*AP14 -> 0 | CJ14: =$G14*AO14*IF($H14>50,18,36)+$F14*AO14*IF($H14>50,4,8)+$E14*AO14 -> 0 | CK14: =$G14*AR14*IF($H14>50,18,36)+$F14*AR14*IF($H14>50,4,8)+$E14*AR14 -> 0 | CL14: =$G14*AS14*IF($H14>50,18,36)+$F14*AS14*IF($H14>50,4,8)+$E14*AS14 -> 0 | CM14: =$G14*AT14*IF($H14>50,18,36)+$F14*AT14*IF($H14>50,4,8)+$E14*AT14 -> 0 | CN14: =$G14*AU14*IF($H14>50,18,36)+$F14*AU14*IF($H14>50,4,8)+$E14*AU14 -> 0 | CO14: =$G14*AV14*IF($H14>50,18,36)+$F14*AV14*IF($H14>50,4,8)+$E14*AV14 -> 0 | CP14: =$G14*AW14*IF($H14>50,18,36)+$F14*AW14*IF($H14>50,4,8)+$E14*AW14 -> 0 | CQ14: =$G14*AX14*IF($H14>50,18,36)+$F14*AX14*IF($H14>50,4,8)+$E14*AX14 -> 0 | CR14: =$G14*AY14*IF($H14>50,18,36)+$F14*AY14*IF($H14>50,4,8)+$E14*AY14 -> 0 | ... CV14: =$G14*BC14*IF($H14>50,18,36)+$F14*BC14*IF($H14>50,4,8)+$E14*BC14 -> 0 | CX14: =O14*BH$2/($H14/50)^2 -> 0 | CY14: =P14*BI$2/($H14/50)^2 -> 0 | CZ14: =Q14*BJ$2/($H14/50)^2 -> 0 | DA14: =R14*BK$2/($H14/50)^2 -> 0 | DB14: =S14*BL$2/($H14/50)^2 -> 0 | DC14: =T14*BM$2/($H14/50)^2 -> 0 | DD14: =U14*BN$2/($H14/50)^2 -> 0 | DE14: =V14*BO$2/($H14/50)^2 -> 0 | ... DJ14: =AA14*BT$2/($H14/50)^2 -> 0 | DK14: =AC14*BU$2/($H14/50)^2 -> 0 | DL14: =AB14*BV$2/($H14/50)^2 -> 0 | DM14: =AD14*BW$2/($H14/50)^2 -> 0 | DN14: =AE14*BX$2/($H14/50)^2 -> 0 | DO14: =AI14*BY$2/($H14/50)^2 -> 0 | DP14: =AF14*BZ$2/($H14/50)^2 -> 0 | DQ14: =AH14*CA$2/($H14/50)^2 -> 0 | DR14: =AG14*CB$2/($H14/50)^2 -> 0 | DS14: =AJ14*CC$2/($H14/50)^2 -> 0 | DT14: =AM14*CD$2/($H14/50)^2 -> 0 | DU14: =AL14*CE$2/($H14/50)^2 -> 0 | DV14: =AK14*CF$2/($H14/50)^2 -> 0 | DW14: =AN14*CG$2/($H14/50)^2 -> 0 | DX14: =AQ14*CH$2/($H14/50)^2 -> 0 | DY14: =AP14*CI$2/($H14/50)^2 -> 0 | DZ14: =AO14*CJ$2/($H14/50)^2 -> 0 | EA14: =AR14*CK$2/($H14/50)^2 -> 0 | EB14: =AS14*CL$2/($H14/50)^2 -> 0 | EC14: =AT14*CM$2/($H14/50)^2 -> 0 | ED14: =AU14*CN$2/($H14/50)^2 -> 0 | EE14: =AV14*CO$2/($H14/50)^2 -> 0 | EF14: =AW14*CP$2/($H14/50)^2 -> 0 | EG14: =AX14*CQ$2/($H14/50)^2 -> 0 | EH14: =AY14*CR$2/($H14/50)^2 -> 0 | ... EL14: =BC14*CV$2/($H14/50)^2 -> 0
A15: Lightness Gum | B15: =IF($C$2,SUMIF(I:I,A15,BG:BG),0) -> 0 | C15: 3 | D15: =C15+B15 -> 3 | E15: =IF(ISBLANK(H15),0,IF($C$1,0,CEILING(D15-F15*H15*0.2-G15*H15,1))) -> 3 | F15: =IF(ISBLANK(H15),0,IF($C$1,0,FLOOR((D15-G15*H15)/(H15/5),1))) -> 0 | G15: =IF(ISBLANK(H15),0,IF($C$1,CEILING(D15/H15,1),FLOOR(D15/H15,1))) -> 0 | H15: 100 | I15: =$A$7 -> Gum Base | J15: =K15*D15 -> 63 | K15: =CEILING(SUM(CX15:EL15),1)+IF(ISBLANK(I15),0,VLOOKUP(I15,A:K,11,FALSE)) -> 21 | L15: - | M15: - | N15: 1 | AH15: 1 | BE15: =IF(ISNUMBER(L15),$G15*L15*25+$F15*L15*10+$E15*L15,0) -> 0 | BF15: =IF(D15>0,M15,0) -> - | BG15: =$G15*N15*IF($H15>50,18,36)+$F15*N15*IF($H15>50,4,8)+$E15*N15 -> 3 | BH15: =$G15*O15*IF($H15>50,18,36)+$F15*O15*IF($H15>50,4,8)+$E15*O15 -> 0 | BI15: =$G15*P15*IF($H15>50,18,36)+$F15*P15*IF($H15>50,4,8)+$E15*P15 -> 0 | BJ15: =$G15*Q15*IF($H15>50,18,36)+$F15*Q15*IF($H15>50,4,8)+$E15*Q15 -> 0 | BK15: =$G15*R15*IF($H15>50,18,36)+$F15*R15*IF($H15>50,4,8)+$E15*R15 -> 0 | BL15: =$G15*S15*IF($H15>50,18,36)+$F15*S15*IF($H15>50,4,8)+$E15*S15 -> 0 | BM15: =$G15*T15*IF($H15>50,18,36)+$F15*T15*IF($H15>50,4,8)+$E15*T15 -> 0 | BN15: =$G15*U15*IF($H15>50,18,36)+$F15*U15*IF($H15>50,4,8)+$E15*U15 -> 0 | ... BT15: =$G15*AA15*IF($H15>50,18,36)+$F15*AA15*IF($H15>50,4,8)+$E15*AA15 -> 0 | BU15: =$G15*AC15*IF($H15>50,18,36)+$F15*AC15*IF($H15>50,4,8)+$E15*AC15 -> 0 | BV15: =$G15*AB15*IF($H15>50,18,36)+$F15*AB15*IF($H15>50,4,8)+$E15*AB15 -> 0 | BW15: =$G15*AD15*IF($H15>50,18,36)+$F15*AD15*IF($H15>50,4,8)+$E15*AD15 -> 0 | BX15: =$G15*AE15*IF($H15>50,18,36)+$F15*AE15*IF($H15>50,4,8)+$E15*AE15 -> 0 | BY15: =$G15*AI15*IF($H15>50,18,36)+$F15*AI15*IF($H15>50,4,8)+$E15*AI15 -> 0 | BZ15: =$G15*AF15*IF($H15>50,18,36)+$F15*AF15*IF($H15>50,4,8)+$E15*AF15 -> 0 | CA15: =$G15*AH15*IF($H15>50,18,36)+$F15*AH15*IF($H15>50,4,8)+$E15*AH15 -> 3 | CB15: =$G15*AG15*IF($H15>50,18,36)+$F15*AG15*IF($H15>50,4,8)+$E15*AG15 -> 0 | CC15: =$G15*AJ15*IF($H15>50,18,36)+$F15*AJ15*IF($H15>50,4,8)+$E15*AJ15 -> 0 | CD15: =$G15*AM15*IF($H15>50,18,36)+$F15*AM15*IF($H15>50,4,8)+$E15*AM15 -> 0 | CE15: =$G15*AL15*IF($H15>50,18,36)+$F15*AL15*IF($H15>50,4,8)+$E15*AL15 -> 0 | CF15: =$G15*AK15*IF($H15>50,18,36)+$F15*AK15*IF($H15>50,4,8)+$E15*AK15 -> 0 | CG15: =$G15*AN15*IF($H15>50,18,36)+$F15*AN15*IF($H15>50,4,8)+$E15*AN15 -> 0 | CH15: =$G15*AQ15*IF($H15>50,18,36)+$F15*AQ15*IF($H15>50,4,8)+$E15*AQ15 -> 0 | CI15: =$G15*AP15*IF($H15>50,18,36)+$F15*AP15*IF($H15>50,4,8)+$E15*AP15 -> 0 | CJ15: =$G15*AO15*IF($H15>50,18,36)+$F15*AO15*IF($H15>50,4,8)+$E15*AO15 -> 0 | CK15: =$G15*AR15*IF($H15>50,18,36)+$F15*AR15*IF($H15>50,4,8)+$E15*AR15 -> 0 | CL15: =$G15*AS15*IF($H15>50,18,36)+$F15*AS15*IF($H15>50,4,8)+$E15*AS15 -> 0 | CM15: =$G15*AT15*IF($H15>50,18,36)+$F15*AT15*IF($H15>50,4,8)+$E15*AT15 -> 0 | CN15: =$G15*AU15*IF($H15>50,18,36)+$F15*AU15*IF($H15>50,4,8)+$E15*AU15 -> 0 | CO15: =$G15*AV15*IF($H15>50,18,36)+$F15*AV15*IF($H15>50,4,8)+$E15*AV15 -> 0 | CP15: =$G15*AW15*IF($H15>50,18,36)+$F15*AW15*IF($H15>50,4,8)+$E15*AW15 -> 0 | CQ15: =$G15*AX15*IF($H15>50,18,36)+$F15*AX15*IF($H15>50,4,8)+$E15*AX15 -> 0 | CR15: =$G15*AY15*IF($H15>50,18,36)+$F15*AY15*IF($H15>50,4,8)+$E15*AY15 -> 0 | ... CV15: =$G15*BC15*IF($H15>50,18,36)+$F15*BC15*IF($H15>50,4,8)+$E15*BC15 -> 0 | CX15: =O15*BH$2/($H15/50)^2 -> 0 | CY15: =P15*BI$2/($H15/50)^2 -> 0 | CZ15: =Q15*BJ$2/($H15/50)^2 -> 0 | DA15: =R15*BK$2/($H15/50)^2 -> 0 | DB15: =S15*BL$2/($H15/50)^2 -> 0 | DC15: =T15*BM$2/($H15/50)^2 -> 0 | DD15: =U15*BN$2/($H15/50)^2 -> 0 | DE15: =V15*BO$2/($H15/50)^2 -> 0 | ... DJ15: =AA15*BT$2/($H15/50)^2 -> 0 | DK15: =AC15*BU$2/($H15/50)^2 -> 0 | DL15: =AB15*BV$2/($H15/50)^2 -> 0 | DM15: =AD15*BW$2/($H15/50)^2 -> 0 | DN15: =AE15*BX$2/($H15/50)^2 -> 0 | DO15: =AI15*BY$2/($H15/50)^2 -> 0 | DP15: =AF15*BZ$2/($H15/50)^2 -> 0 | DQ15: =AH15*CA$2/($H15/50)^2 -> 8.75 | DR15: =AG15*CB$2/($H15/50)^2 -> 0 | DS15: =AJ15*CC$2/($H15/50)^2 -> 0 | DT15: =AM15*CD$2/($H15/50)^2 -> 0 | DU15: =AL15*CE$2/($H15/50)^2 -> 0 | DV15: =AK15*CF$2/($H15/50)^2 -> 0 | DW15: =AN15*CG$2/($H15/50)^2 -> 0 | DX15: =AQ15*CH$2/($H15/50)^2 -> 0 | DY15: =AP15*CI$2/($H15/50)^2 -> 0 | DZ15: =AO15*CJ$2/($H15/50)^2 -> 0 | EA15: =AR15*CK$2/($H15/50)^2 -> 0 | EB15: =AS15*CL$2/($H15/50)^2 -> 0 | EC15: =AT15*CM$2/($H15/50)^2 -> 0 | ED15: =AU15*CN$2/($H15/50)^2 -> 0 | EE15: =AV15*CO$2/($H15/50)^2 -> 0 | EF15: =AW15*CP$2/($H15/50)^2 -> 0 | EG15: =AX15*CQ$2/($H15/50)^2 -> 0 | EH15: =AY15*CR$2/($H15/50)^2 -> 0 | ... EL15: =BC15*CV$2/($H15/50)^2 -> 0
